{
 "cells": [
  {
   "cell_type": "code",
   "execution_count": 6,
   "metadata": {},
   "outputs": [],
   "source": [
    "from sklearn.base import BaseEstimator, TransformerMixin\n",
    "from sklearn.linear_model import LinearRegression\n",
    "from sklearn.model_selection import TimeSeriesSplit\n",
    "from sklearn import svm\n",
    "from sklearn.preprocessing import Normalizer\n",
    "from sklearn.neural_network import MLPRegressor\n",
    "from sklearn.metrics import mean_squared_error, mean_absolute_error, r2_score\n",
    "from sklearn.model_selection import GridSearchCV\n",
    "from sklearn.pipeline import Pipeline\n",
    "from sklearn.preprocessing import PolynomialFeatures\n",
    "from sklearn.compose import ColumnTransformer\n",
    "from sklearn.preprocessing import OneHotEncoder\n",
    "from sklearn.linear_model import Ridge\n",
    "\n",
    "from LSSVMRegression import LSSVMRegression\n",
    "\n",
    "from windTransformer import WindVectorTransformer\n",
    "from windTransformer import WindDegreeTransformer\n",
    "from windData import WindDataCollector\n",
    "\n",
    "import matplotlib.pyplot as plt\n",
    "\n",
    "import numpy as np\n",
    "import math\n",
    "import pandas as pd\n",
    "\n",
    "from influxdb import InfluxDBClient # install via \"pip install influxdb\"\n",
    "\n",
    "import datetime"
   ]
  },
  {
   "cell_type": "code",
   "execution_count": 7,
   "metadata": {},
   "outputs": [],
   "source": [
    "def eval_metrics(actual, pred):\n",
    "\trmse = np.sqrt(mean_squared_error(actual, pred))\n",
    "\tmae = mean_absolute_error(actual, pred)\n",
    "\tr2 = r2_score(actual, pred)\n",
    "\treturn rmse, mae, r2\n"
   ]
  },
  {
   "attachments": {},
   "cell_type": "markdown",
   "metadata": {},
   "source": [
    "## Data prep"
   ]
  },
  {
   "cell_type": "code",
   "execution_count": 8,
   "metadata": {},
   "outputs": [],
   "source": [
    "start_time = datetime.datetime(2021, 1, 1, 0, 0, 0).strftime(\"'%Y-%m-%dT%H:%M:%SZ'\")\n",
    "\n",
    "\n",
    "dataCollector = WindDataCollector()\n",
    "\n",
    "gen_df = dataCollector.getGenerationData(now = start_time, delta=\"90\")\n",
    "wind_df = dataCollector.getWindData(now = start_time, delta=\"90\")\n",
    "\n",
    "gen_df_alligned = pd.merge_asof(wind_df,gen_df,left_index=True, right_index=True)"
   ]
  },
  {
   "cell_type": "code",
   "execution_count": 9,
   "metadata": {},
   "outputs": [],
   "source": [
    "train_length = int(len(gen_df_alligned)*0.9)\n",
    "\n",
    "train_X = gen_df_alligned.iloc[:train_length][[\n",
    "#    \"Direction\",\n",
    "    \"Speed\"]]\n",
    "test_X = gen_df_alligned.iloc[train_length:][[\n",
    "#    \"Direction\",\n",
    "    \"Speed\"]]\n",
    "\n",
    "train_y = gen_df_alligned.iloc[:train_length][\"Total\"]\n",
    "test_y = gen_df_alligned.iloc[train_length:][\"Total\"]"
   ]
  },
  {
   "cell_type": "code",
   "execution_count": 10,
   "metadata": {},
   "outputs": [],
   "source": [
    "import plotly.express as px\n",
    "\n",
    "\n",
    "# fig = px.scatter(gen_df_alligned, x=\"Speed\", y=\"Total\")\n",
    "# fig.show()"
   ]
  },
  {
   "cell_type": "markdown",
   "metadata": {},
   "source": [
    "## Linear regression\n",
    "\n",
    "https://scikit-learn.org/stable/modules/generated/sklearn.linear_model.LinearRegression.html"
   ]
  },
  {
   "cell_type": "code",
   "execution_count": 27,
   "metadata": {},
   "outputs": [
    {
     "ename": "SyntaxError",
     "evalue": "unmatched ')' (2029095877.py, line 5)",
     "output_type": "error",
     "traceback": [
      "\u001b[0;36m  Input \u001b[0;32mIn [27]\u001b[0;36m\u001b[0m\n\u001b[0;31m    ])),\u001b[0m\n\u001b[0m      ^\u001b[0m\n\u001b[0;31mSyntaxError\u001b[0m\u001b[0;31m:\u001b[0m unmatched ')'\n"
     ]
    }
   ],
   "source": [
    "pipeline = Pipeline(steps=[\n",
    "    # (\"column_transformers\", ColumnTransformer([\n",
    "#        (\"direction_degree_transformer\", WindDegreeTransformer(), [\"Direction\"]),\n",
    "        # (\"polynomial_features\", PolynomialFeatures() , [\"Speed\"])\n",
    "    ])),\n",
    "\t(\"mlp_model\", MLPRegressor((32, 16), \n",
    "    activation=\"relu\", \n",
    "    solver=\"sgd\", \n",
    "    # batch_size=32,\n",
    "    learning_rate_init=0.1, \n",
    "    max_iter=80,\n",
    "    ))\n",
    "])\n",
    "parameters = {\n",
    "\t# 'column_transformers__polynomial_features__degree':[1,2,3,4,5,6,7,8]\n",
    "}"
   ]
  },
  {
   "cell_type": "code",
   "execution_count": 28,
   "metadata": {},
   "outputs": [
    {
     "ename": "ValueError",
     "evalue": "\nAll the 5 fits failed.\nIt is very likely that your model is misconfigured.\nYou can try to debug the error by setting error_score='raise'.\n\nBelow are more details about the failures:\n--------------------------------------------------------------------------------\n1 fits failed with the following error:\nTraceback (most recent call last):\n  File \"/Users/Thomas/opt/anaconda3/envs/wild/lib/python3.9/site-packages/sklearn/model_selection/_validation.py\", line 686, in _fit_and_score\n    estimator.fit(X_train, y_train, **fit_params)\n  File \"/Users/Thomas/opt/anaconda3/envs/wild/lib/python3.9/site-packages/sklearn/model_selection/_search.py\", line 875, in fit\n    self._run_search(evaluate_candidates)\n  File \"/Users/Thomas/opt/anaconda3/envs/wild/lib/python3.9/site-packages/sklearn/model_selection/_search.py\", line 1379, in _run_search\n    evaluate_candidates(ParameterGrid(self.param_grid))\n  File \"/Users/Thomas/opt/anaconda3/envs/wild/lib/python3.9/site-packages/sklearn/model_selection/_search.py\", line 852, in evaluate_candidates\n    _warn_or_raise_about_fit_failures(out, self.error_score)\n  File \"/Users/Thomas/opt/anaconda3/envs/wild/lib/python3.9/site-packages/sklearn/model_selection/_validation.py\", line 367, in _warn_or_raise_about_fit_failures\n    raise ValueError(all_fits_failed_message)\nValueError: \nAll the 5 fits failed.\nIt is very likely that your model is misconfigured.\nYou can try to debug the error by setting error_score='raise'.\n\nBelow are more details about the failures:\n--------------------------------------------------------------------------------\n1 fits failed with the following error:\nTraceback (most recent call last):\n  File \"/Users/Thomas/opt/anaconda3/envs/wild/lib/python3.9/site-packages/sklearn/model_selection/_validation.py\", line 686, in _fit_and_score\n    estimator.fit(X_train, y_train, **fit_params)\n  File \"/Users/Thomas/opt/anaconda3/envs/wild/lib/python3.9/site-packages/sklearn/pipeline.py\", line 382, in fit\n    self._final_estimator.fit(Xt, y, **fit_params_last_step)\n  File \"/Users/Thomas/opt/anaconda3/envs/wild/lib/python3.9/site-packages/sklearn/neural_network/_multilayer_perceptron.py\", line 762, in fit\n    return self._fit(X, y, incremental=False)\n  File \"/Users/Thomas/opt/anaconda3/envs/wild/lib/python3.9/site-packages/sklearn/neural_network/_multilayer_perceptron.py\", line 394, in _fit\n    X, y = self._validate_input(X, y, incremental, reset=first_pass)\n  File \"/Users/Thomas/opt/anaconda3/envs/wild/lib/python3.9/site-packages/sklearn/neural_network/_multilayer_perceptron.py\", line 1597, in _validate_input\n    X, y = self._validate_data(\n  File \"/Users/Thomas/opt/anaconda3/envs/wild/lib/python3.9/site-packages/sklearn/base.py\", line 596, in _validate_data\n    X, y = check_X_y(X, y, **check_params)\n  File \"/Users/Thomas/opt/anaconda3/envs/wild/lib/python3.9/site-packages/sklearn/utils/validation.py\", line 1074, in check_X_y\n    X = check_array(\n  File \"/Users/Thomas/opt/anaconda3/envs/wild/lib/python3.9/site-packages/sklearn/utils/validation.py\", line 918, in check_array\n    raise ValueError(\nValueError: Found array with 0 feature(s) (shape=(20, 0)) while a minimum of 1 is required by MLPRegressor.\n\n--------------------------------------------------------------------------------\n1 fits failed with the following error:\nTraceback (most recent call last):\n  File \"/Users/Thomas/opt/anaconda3/envs/wild/lib/python3.9/site-packages/sklearn/model_selection/_validation.py\", line 686, in _fit_and_score\n    estimator.fit(X_train, y_train, **fit_params)\n  File \"/Users/Thomas/opt/anaconda3/envs/wild/lib/python3.9/site-packages/sklearn/pipeline.py\", line 382, in fit\n    self._final_estimator.fit(Xt, y, **fit_params_last_step)\n  File \"/Users/Thomas/opt/anaconda3/envs/wild/lib/python3.9/site-packages/sklearn/neural_network/_multilayer_perceptron.py\", line 762, in fit\n    return self._fit(X, y, incremental=False)\n  File \"/Users/Thomas/opt/anaconda3/envs/wild/lib/python3.9/site-packages/sklearn/neural_network/_multilayer_perceptron.py\", line 394, in _fit\n    X, y = self._validate_input(X, y, incremental, reset=first_pass)\n  File \"/Users/Thomas/opt/anaconda3/envs/wild/lib/python3.9/site-packages/sklearn/neural_network/_multilayer_perceptron.py\", line 1597, in _validate_input\n    X, y = self._validate_data(\n  File \"/Users/Thomas/opt/anaconda3/envs/wild/lib/python3.9/site-packages/sklearn/base.py\", line 596, in _validate_data\n    X, y = check_X_y(X, y, **check_params)\n  File \"/Users/Thomas/opt/anaconda3/envs/wild/lib/python3.9/site-packages/sklearn/utils/validation.py\", line 1074, in check_X_y\n    X = check_array(\n  File \"/Users/Thomas/opt/anaconda3/envs/wild/lib/python3.9/site-packages/sklearn/utils/validation.py\", line 918, in check_array\n    raise ValueError(\nValueError: Found array with 0 feature(s) (shape=(35, 0)) while a minimum of 1 is required by MLPRegressor.\n\n--------------------------------------------------------------------------------\n1 fits failed with the following error:\nTraceback (most recent call last):\n  File \"/Users/Thomas/opt/anaconda3/envs/wild/lib/python3.9/site-packages/sklearn/model_selection/_validation.py\", line 686, in _fit_and_score\n    estimator.fit(X_train, y_train, **fit_params)\n  File \"/Users/Thomas/opt/anaconda3/envs/wild/lib/python3.9/site-packages/sklearn/pipeline.py\", line 382, in fit\n    self._final_estimator.fit(Xt, y, **fit_params_last_step)\n  File \"/Users/Thomas/opt/anaconda3/envs/wild/lib/python3.9/site-packages/sklearn/neural_network/_multilayer_perceptron.py\", line 762, in fit\n    return self._fit(X, y, incremental=False)\n  File \"/Users/Thomas/opt/anaconda3/envs/wild/lib/python3.9/site-packages/sklearn/neural_network/_multilayer_perceptron.py\", line 394, in _fit\n    X, y = self._validate_input(X, y, incremental, reset=first_pass)\n  File \"/Users/Thomas/opt/anaconda3/envs/wild/lib/python3.9/site-packages/sklearn/neural_network/_multilayer_perceptron.py\", line 1597, in _validate_input\n    X, y = self._validate_data(\n  File \"/Users/Thomas/opt/anaconda3/envs/wild/lib/python3.9/site-packages/sklearn/base.py\", line 596, in _validate_data\n    X, y = check_X_y(X, y, **check_params)\n  File \"/Users/Thomas/opt/anaconda3/envs/wild/lib/python3.9/site-packages/sklearn/utils/validation.py\", line 1074, in check_X_y\n    X = check_array(\n  File \"/Users/Thomas/opt/anaconda3/envs/wild/lib/python3.9/site-packages/sklearn/utils/validation.py\", line 918, in check_array\n    raise ValueError(\nValueError: Found array with 0 feature(s) (shape=(50, 0)) while a minimum of 1 is required by MLPRegressor.\n\n--------------------------------------------------------------------------------\n1 fits failed with the following error:\nTraceback (most recent call last):\n  File \"/Users/Thomas/opt/anaconda3/envs/wild/lib/python3.9/site-packages/sklearn/model_selection/_validation.py\", line 686, in _fit_and_score\n    estimator.fit(X_train, y_train, **fit_params)\n  File \"/Users/Thomas/opt/anaconda3/envs/wild/lib/python3.9/site-packages/sklearn/pipeline.py\", line 382, in fit\n    self._final_estimator.fit(Xt, y, **fit_params_last_step)\n  File \"/Users/Thomas/opt/anaconda3/envs/wild/lib/python3.9/site-packages/sklearn/neural_network/_multilayer_perceptron.py\", line 762, in fit\n    return self._fit(X, y, incremental=False)\n  File \"/Users/Thomas/opt/anaconda3/envs/wild/lib/python3.9/site-packages/sklearn/neural_network/_multilayer_perceptron.py\", line 394, in _fit\n    X, y = self._validate_input(X, y, incremental, reset=first_pass)\n  File \"/Users/Thomas/opt/anaconda3/envs/wild/lib/python3.9/site-packages/sklearn/neural_network/_multilayer_perceptron.py\", line 1597, in _validate_input\n    X, y = self._validate_data(\n  File \"/Users/Thomas/opt/anaconda3/envs/wild/lib/python3.9/site-packages/sklearn/base.py\", line 596, in _validate_data\n    X, y = check_X_y(X, y, **check_params)\n  File \"/Users/Thomas/opt/anaconda3/envs/wild/lib/python3.9/site-packages/sklearn/utils/validation.py\", line 1074, in check_X_y\n    X = check_array(\n  File \"/Users/Thomas/opt/anaconda3/envs/wild/lib/python3.9/site-packages/sklearn/utils/validation.py\", line 918, in check_array\n    raise ValueError(\nValueError: Found array with 0 feature(s) (shape=(65, 0)) while a minimum of 1 is required by MLPRegressor.\n\n--------------------------------------------------------------------------------\n1 fits failed with the following error:\nTraceback (most recent call last):\n  File \"/Users/Thomas/opt/anaconda3/envs/wild/lib/python3.9/site-packages/sklearn/model_selection/_validation.py\", line 686, in _fit_and_score\n    estimator.fit(X_train, y_train, **fit_params)\n  File \"/Users/Thomas/opt/anaconda3/envs/wild/lib/python3.9/site-packages/sklearn/pipeline.py\", line 382, in fit\n    self._final_estimator.fit(Xt, y, **fit_params_last_step)\n  File \"/Users/Thomas/opt/anaconda3/envs/wild/lib/python3.9/site-packages/sklearn/neural_network/_multilayer_perceptron.py\", line 762, in fit\n    return self._fit(X, y, incremental=False)\n  File \"/Users/Thomas/opt/anaconda3/envs/wild/lib/python3.9/site-packages/sklearn/neural_network/_multilayer_perceptron.py\", line 394, in _fit\n    X, y = self._validate_input(X, y, incremental, reset=first_pass)\n  File \"/Users/Thomas/opt/anaconda3/envs/wild/lib/python3.9/site-packages/sklearn/neural_network/_multilayer_perceptron.py\", line 1597, in _validate_input\n    X, y = self._validate_data(\n  File \"/Users/Thomas/opt/anaconda3/envs/wild/lib/python3.9/site-packages/sklearn/base.py\", line 596, in _validate_data\n    X, y = check_X_y(X, y, **check_params)\n  File \"/Users/Thomas/opt/anaconda3/envs/wild/lib/python3.9/site-packages/sklearn/utils/validation.py\", line 1074, in check_X_y\n    X = check_array(\n  File \"/Users/Thomas/opt/anaconda3/envs/wild/lib/python3.9/site-packages/sklearn/utils/validation.py\", line 918, in check_array\n    raise ValueError(\nValueError: Found array with 0 feature(s) (shape=(80, 0)) while a minimum of 1 is required by MLPRegressor.\n\n\n--------------------------------------------------------------------------------\n1 fits failed with the following error:\nTraceback (most recent call last):\n  File \"/Users/Thomas/opt/anaconda3/envs/wild/lib/python3.9/site-packages/sklearn/model_selection/_validation.py\", line 686, in _fit_and_score\n    estimator.fit(X_train, y_train, **fit_params)\n  File \"/Users/Thomas/opt/anaconda3/envs/wild/lib/python3.9/site-packages/sklearn/model_selection/_search.py\", line 875, in fit\n    self._run_search(evaluate_candidates)\n  File \"/Users/Thomas/opt/anaconda3/envs/wild/lib/python3.9/site-packages/sklearn/model_selection/_search.py\", line 1379, in _run_search\n    evaluate_candidates(ParameterGrid(self.param_grid))\n  File \"/Users/Thomas/opt/anaconda3/envs/wild/lib/python3.9/site-packages/sklearn/model_selection/_search.py\", line 852, in evaluate_candidates\n    _warn_or_raise_about_fit_failures(out, self.error_score)\n  File \"/Users/Thomas/opt/anaconda3/envs/wild/lib/python3.9/site-packages/sklearn/model_selection/_validation.py\", line 367, in _warn_or_raise_about_fit_failures\n    raise ValueError(all_fits_failed_message)\nValueError: \nAll the 5 fits failed.\nIt is very likely that your model is misconfigured.\nYou can try to debug the error by setting error_score='raise'.\n\nBelow are more details about the failures:\n--------------------------------------------------------------------------------\n1 fits failed with the following error:\nTraceback (most recent call last):\n  File \"/Users/Thomas/opt/anaconda3/envs/wild/lib/python3.9/site-packages/sklearn/model_selection/_validation.py\", line 686, in _fit_and_score\n    estimator.fit(X_train, y_train, **fit_params)\n  File \"/Users/Thomas/opt/anaconda3/envs/wild/lib/python3.9/site-packages/sklearn/pipeline.py\", line 382, in fit\n    self._final_estimator.fit(Xt, y, **fit_params_last_step)\n  File \"/Users/Thomas/opt/anaconda3/envs/wild/lib/python3.9/site-packages/sklearn/neural_network/_multilayer_perceptron.py\", line 762, in fit\n    return self._fit(X, y, incremental=False)\n  File \"/Users/Thomas/opt/anaconda3/envs/wild/lib/python3.9/site-packages/sklearn/neural_network/_multilayer_perceptron.py\", line 394, in _fit\n    X, y = self._validate_input(X, y, incremental, reset=first_pass)\n  File \"/Users/Thomas/opt/anaconda3/envs/wild/lib/python3.9/site-packages/sklearn/neural_network/_multilayer_perceptron.py\", line 1597, in _validate_input\n    X, y = self._validate_data(\n  File \"/Users/Thomas/opt/anaconda3/envs/wild/lib/python3.9/site-packages/sklearn/base.py\", line 596, in _validate_data\n    X, y = check_X_y(X, y, **check_params)\n  File \"/Users/Thomas/opt/anaconda3/envs/wild/lib/python3.9/site-packages/sklearn/utils/validation.py\", line 1074, in check_X_y\n    X = check_array(\n  File \"/Users/Thomas/opt/anaconda3/envs/wild/lib/python3.9/site-packages/sklearn/utils/validation.py\", line 918, in check_array\n    raise ValueError(\nValueError: Found array with 0 feature(s) (shape=(33, 0)) while a minimum of 1 is required by MLPRegressor.\n\n--------------------------------------------------------------------------------\n1 fits failed with the following error:\nTraceback (most recent call last):\n  File \"/Users/Thomas/opt/anaconda3/envs/wild/lib/python3.9/site-packages/sklearn/model_selection/_validation.py\", line 686, in _fit_and_score\n    estimator.fit(X_train, y_train, **fit_params)\n  File \"/Users/Thomas/opt/anaconda3/envs/wild/lib/python3.9/site-packages/sklearn/pipeline.py\", line 382, in fit\n    self._final_estimator.fit(Xt, y, **fit_params_last_step)\n  File \"/Users/Thomas/opt/anaconda3/envs/wild/lib/python3.9/site-packages/sklearn/neural_network/_multilayer_perceptron.py\", line 762, in fit\n    return self._fit(X, y, incremental=False)\n  File \"/Users/Thomas/opt/anaconda3/envs/wild/lib/python3.9/site-packages/sklearn/neural_network/_multilayer_perceptron.py\", line 394, in _fit\n    X, y = self._validate_input(X, y, incremental, reset=first_pass)\n  File \"/Users/Thomas/opt/anaconda3/envs/wild/lib/python3.9/site-packages/sklearn/neural_network/_multilayer_perceptron.py\", line 1597, in _validate_input\n    X, y = self._validate_data(\n  File \"/Users/Thomas/opt/anaconda3/envs/wild/lib/python3.9/site-packages/sklearn/base.py\", line 596, in _validate_data\n    X, y = check_X_y(X, y, **check_params)\n  File \"/Users/Thomas/opt/anaconda3/envs/wild/lib/python3.9/site-packages/sklearn/utils/validation.py\", line 1074, in check_X_y\n    X = check_array(\n  File \"/Users/Thomas/opt/anaconda3/envs/wild/lib/python3.9/site-packages/sklearn/utils/validation.py\", line 918, in check_array\n    raise ValueError(\nValueError: Found array with 0 feature(s) (shape=(64, 0)) while a minimum of 1 is required by MLPRegressor.\n\n--------------------------------------------------------------------------------\n1 fits failed with the following error:\nTraceback (most recent call last):\n  File \"/Users/Thomas/opt/anaconda3/envs/wild/lib/python3.9/site-packages/sklearn/model_selection/_validation.py\", line 686, in _fit_and_score\n    estimator.fit(X_train, y_train, **fit_params)\n  File \"/Users/Thomas/opt/anaconda3/envs/wild/lib/python3.9/site-packages/sklearn/pipeline.py\", line 382, in fit\n    self._final_estimator.fit(Xt, y, **fit_params_last_step)\n  File \"/Users/Thomas/opt/anaconda3/envs/wild/lib/python3.9/site-packages/sklearn/neural_network/_multilayer_perceptron.py\", line 762, in fit\n    return self._fit(X, y, incremental=False)\n  File \"/Users/Thomas/opt/anaconda3/envs/wild/lib/python3.9/site-packages/sklearn/neural_network/_multilayer_perceptron.py\", line 394, in _fit\n    X, y = self._validate_input(X, y, incremental, reset=first_pass)\n  File \"/Users/Thomas/opt/anaconda3/envs/wild/lib/python3.9/site-packages/sklearn/neural_network/_multilayer_perceptron.py\", line 1597, in _validate_input\n    X, y = self._validate_data(\n  File \"/Users/Thomas/opt/anaconda3/envs/wild/lib/python3.9/site-packages/sklearn/base.py\", line 596, in _validate_data\n    X, y = check_X_y(X, y, **check_params)\n  File \"/Users/Thomas/opt/anaconda3/envs/wild/lib/python3.9/site-packages/sklearn/utils/validation.py\", line 1074, in check_X_y\n    X = check_array(\n  File \"/Users/Thomas/opt/anaconda3/envs/wild/lib/python3.9/site-packages/sklearn/utils/validation.py\", line 918, in check_array\n    raise ValueError(\nValueError: Found array with 0 feature(s) (shape=(95, 0)) while a minimum of 1 is required by MLPRegressor.\n\n--------------------------------------------------------------------------------\n1 fits failed with the following error:\nTraceback (most recent call last):\n  File \"/Users/Thomas/opt/anaconda3/envs/wild/lib/python3.9/site-packages/sklearn/model_selection/_validation.py\", line 686, in _fit_and_score\n    estimator.fit(X_train, y_train, **fit_params)\n  File \"/Users/Thomas/opt/anaconda3/envs/wild/lib/python3.9/site-packages/sklearn/pipeline.py\", line 382, in fit\n    self._final_estimator.fit(Xt, y, **fit_params_last_step)\n  File \"/Users/Thomas/opt/anaconda3/envs/wild/lib/python3.9/site-packages/sklearn/neural_network/_multilayer_perceptron.py\", line 762, in fit\n    return self._fit(X, y, incremental=False)\n  File \"/Users/Thomas/opt/anaconda3/envs/wild/lib/python3.9/site-packages/sklearn/neural_network/_multilayer_perceptron.py\", line 394, in _fit\n    X, y = self._validate_input(X, y, incremental, reset=first_pass)\n  File \"/Users/Thomas/opt/anaconda3/envs/wild/lib/python3.9/site-packages/sklearn/neural_network/_multilayer_perceptron.py\", line 1597, in _validate_input\n    X, y = self._validate_data(\n  File \"/Users/Thomas/opt/anaconda3/envs/wild/lib/python3.9/site-packages/sklearn/base.py\", line 596, in _validate_data\n    X, y = check_X_y(X, y, **check_params)\n  File \"/Users/Thomas/opt/anaconda3/envs/wild/lib/python3.9/site-packages/sklearn/utils/validation.py\", line 1074, in check_X_y\n    X = check_array(\n  File \"/Users/Thomas/opt/anaconda3/envs/wild/lib/python3.9/site-packages/sklearn/utils/validation.py\", line 918, in check_array\n    raise ValueError(\nValueError: Found array with 0 feature(s) (shape=(126, 0)) while a minimum of 1 is required by MLPRegressor.\n\n--------------------------------------------------------------------------------\n1 fits failed with the following error:\nTraceback (most recent call last):\n  File \"/Users/Thomas/opt/anaconda3/envs/wild/lib/python3.9/site-packages/sklearn/model_selection/_validation.py\", line 686, in _fit_and_score\n    estimator.fit(X_train, y_train, **fit_params)\n  File \"/Users/Thomas/opt/anaconda3/envs/wild/lib/python3.9/site-packages/sklearn/pipeline.py\", line 382, in fit\n    self._final_estimator.fit(Xt, y, **fit_params_last_step)\n  File \"/Users/Thomas/opt/anaconda3/envs/wild/lib/python3.9/site-packages/sklearn/neural_network/_multilayer_perceptron.py\", line 762, in fit\n    return self._fit(X, y, incremental=False)\n  File \"/Users/Thomas/opt/anaconda3/envs/wild/lib/python3.9/site-packages/sklearn/neural_network/_multilayer_perceptron.py\", line 394, in _fit\n    X, y = self._validate_input(X, y, incremental, reset=first_pass)\n  File \"/Users/Thomas/opt/anaconda3/envs/wild/lib/python3.9/site-packages/sklearn/neural_network/_multilayer_perceptron.py\", line 1597, in _validate_input\n    X, y = self._validate_data(\n  File \"/Users/Thomas/opt/anaconda3/envs/wild/lib/python3.9/site-packages/sklearn/base.py\", line 596, in _validate_data\n    X, y = check_X_y(X, y, **check_params)\n  File \"/Users/Thomas/opt/anaconda3/envs/wild/lib/python3.9/site-packages/sklearn/utils/validation.py\", line 1074, in check_X_y\n    X = check_array(\n  File \"/Users/Thomas/opt/anaconda3/envs/wild/lib/python3.9/site-packages/sklearn/utils/validation.py\", line 918, in check_array\n    raise ValueError(\nValueError: Found array with 0 feature(s) (shape=(157, 0)) while a minimum of 1 is required by MLPRegressor.\n\n\n--------------------------------------------------------------------------------\n1 fits failed with the following error:\nTraceback (most recent call last):\n  File \"/Users/Thomas/opt/anaconda3/envs/wild/lib/python3.9/site-packages/sklearn/model_selection/_validation.py\", line 686, in _fit_and_score\n    estimator.fit(X_train, y_train, **fit_params)\n  File \"/Users/Thomas/opt/anaconda3/envs/wild/lib/python3.9/site-packages/sklearn/model_selection/_search.py\", line 875, in fit\n    self._run_search(evaluate_candidates)\n  File \"/Users/Thomas/opt/anaconda3/envs/wild/lib/python3.9/site-packages/sklearn/model_selection/_search.py\", line 1379, in _run_search\n    evaluate_candidates(ParameterGrid(self.param_grid))\n  File \"/Users/Thomas/opt/anaconda3/envs/wild/lib/python3.9/site-packages/sklearn/model_selection/_search.py\", line 852, in evaluate_candidates\n    _warn_or_raise_about_fit_failures(out, self.error_score)\n  File \"/Users/Thomas/opt/anaconda3/envs/wild/lib/python3.9/site-packages/sklearn/model_selection/_validation.py\", line 367, in _warn_or_raise_about_fit_failures\n    raise ValueError(all_fits_failed_message)\nValueError: \nAll the 5 fits failed.\nIt is very likely that your model is misconfigured.\nYou can try to debug the error by setting error_score='raise'.\n\nBelow are more details about the failures:\n--------------------------------------------------------------------------------\n1 fits failed with the following error:\nTraceback (most recent call last):\n  File \"/Users/Thomas/opt/anaconda3/envs/wild/lib/python3.9/site-packages/sklearn/model_selection/_validation.py\", line 686, in _fit_and_score\n    estimator.fit(X_train, y_train, **fit_params)\n  File \"/Users/Thomas/opt/anaconda3/envs/wild/lib/python3.9/site-packages/sklearn/pipeline.py\", line 382, in fit\n    self._final_estimator.fit(Xt, y, **fit_params_last_step)\n  File \"/Users/Thomas/opt/anaconda3/envs/wild/lib/python3.9/site-packages/sklearn/neural_network/_multilayer_perceptron.py\", line 762, in fit\n    return self._fit(X, y, incremental=False)\n  File \"/Users/Thomas/opt/anaconda3/envs/wild/lib/python3.9/site-packages/sklearn/neural_network/_multilayer_perceptron.py\", line 394, in _fit\n    X, y = self._validate_input(X, y, incremental, reset=first_pass)\n  File \"/Users/Thomas/opt/anaconda3/envs/wild/lib/python3.9/site-packages/sklearn/neural_network/_multilayer_perceptron.py\", line 1597, in _validate_input\n    X, y = self._validate_data(\n  File \"/Users/Thomas/opt/anaconda3/envs/wild/lib/python3.9/site-packages/sklearn/base.py\", line 596, in _validate_data\n    X, y = check_X_y(X, y, **check_params)\n  File \"/Users/Thomas/opt/anaconda3/envs/wild/lib/python3.9/site-packages/sklearn/utils/validation.py\", line 1074, in check_X_y\n    X = check_array(\n  File \"/Users/Thomas/opt/anaconda3/envs/wild/lib/python3.9/site-packages/sklearn/utils/validation.py\", line 918, in check_array\n    raise ValueError(\nValueError: Found array with 0 feature(s) (shape=(51, 0)) while a minimum of 1 is required by MLPRegressor.\n\n--------------------------------------------------------------------------------\n1 fits failed with the following error:\nTraceback (most recent call last):\n  File \"/Users/Thomas/opt/anaconda3/envs/wild/lib/python3.9/site-packages/sklearn/model_selection/_validation.py\", line 686, in _fit_and_score\n    estimator.fit(X_train, y_train, **fit_params)\n  File \"/Users/Thomas/opt/anaconda3/envs/wild/lib/python3.9/site-packages/sklearn/pipeline.py\", line 382, in fit\n    self._final_estimator.fit(Xt, y, **fit_params_last_step)\n  File \"/Users/Thomas/opt/anaconda3/envs/wild/lib/python3.9/site-packages/sklearn/neural_network/_multilayer_perceptron.py\", line 762, in fit\n    return self._fit(X, y, incremental=False)\n  File \"/Users/Thomas/opt/anaconda3/envs/wild/lib/python3.9/site-packages/sklearn/neural_network/_multilayer_perceptron.py\", line 394, in _fit\n    X, y = self._validate_input(X, y, incremental, reset=first_pass)\n  File \"/Users/Thomas/opt/anaconda3/envs/wild/lib/python3.9/site-packages/sklearn/neural_network/_multilayer_perceptron.py\", line 1597, in _validate_input\n    X, y = self._validate_data(\n  File \"/Users/Thomas/opt/anaconda3/envs/wild/lib/python3.9/site-packages/sklearn/base.py\", line 596, in _validate_data\n    X, y = check_X_y(X, y, **check_params)\n  File \"/Users/Thomas/opt/anaconda3/envs/wild/lib/python3.9/site-packages/sklearn/utils/validation.py\", line 1074, in check_X_y\n    X = check_array(\n  File \"/Users/Thomas/opt/anaconda3/envs/wild/lib/python3.9/site-packages/sklearn/utils/validation.py\", line 918, in check_array\n    raise ValueError(\nValueError: Found array with 0 feature(s) (shape=(97, 0)) while a minimum of 1 is required by MLPRegressor.\n\n--------------------------------------------------------------------------------\n1 fits failed with the following error:\nTraceback (most recent call last):\n  File \"/Users/Thomas/opt/anaconda3/envs/wild/lib/python3.9/site-packages/sklearn/model_selection/_validation.py\", line 686, in _fit_and_score\n    estimator.fit(X_train, y_train, **fit_params)\n  File \"/Users/Thomas/opt/anaconda3/envs/wild/lib/python3.9/site-packages/sklearn/pipeline.py\", line 382, in fit\n    self._final_estimator.fit(Xt, y, **fit_params_last_step)\n  File \"/Users/Thomas/opt/anaconda3/envs/wild/lib/python3.9/site-packages/sklearn/neural_network/_multilayer_perceptron.py\", line 762, in fit\n    return self._fit(X, y, incremental=False)\n  File \"/Users/Thomas/opt/anaconda3/envs/wild/lib/python3.9/site-packages/sklearn/neural_network/_multilayer_perceptron.py\", line 394, in _fit\n    X, y = self._validate_input(X, y, incremental, reset=first_pass)\n  File \"/Users/Thomas/opt/anaconda3/envs/wild/lib/python3.9/site-packages/sklearn/neural_network/_multilayer_perceptron.py\", line 1597, in _validate_input\n    X, y = self._validate_data(\n  File \"/Users/Thomas/opt/anaconda3/envs/wild/lib/python3.9/site-packages/sklearn/base.py\", line 596, in _validate_data\n    X, y = check_X_y(X, y, **check_params)\n  File \"/Users/Thomas/opt/anaconda3/envs/wild/lib/python3.9/site-packages/sklearn/utils/validation.py\", line 1074, in check_X_y\n    X = check_array(\n  File \"/Users/Thomas/opt/anaconda3/envs/wild/lib/python3.9/site-packages/sklearn/utils/validation.py\", line 918, in check_array\n    raise ValueError(\nValueError: Found array with 0 feature(s) (shape=(143, 0)) while a minimum of 1 is required by MLPRegressor.\n\n--------------------------------------------------------------------------------\n1 fits failed with the following error:\nTraceback (most recent call last):\n  File \"/Users/Thomas/opt/anaconda3/envs/wild/lib/python3.9/site-packages/sklearn/model_selection/_validation.py\", line 686, in _fit_and_score\n    estimator.fit(X_train, y_train, **fit_params)\n  File \"/Users/Thomas/opt/anaconda3/envs/wild/lib/python3.9/site-packages/sklearn/pipeline.py\", line 382, in fit\n    self._final_estimator.fit(Xt, y, **fit_params_last_step)\n  File \"/Users/Thomas/opt/anaconda3/envs/wild/lib/python3.9/site-packages/sklearn/neural_network/_multilayer_perceptron.py\", line 762, in fit\n    return self._fit(X, y, incremental=False)\n  File \"/Users/Thomas/opt/anaconda3/envs/wild/lib/python3.9/site-packages/sklearn/neural_network/_multilayer_perceptron.py\", line 394, in _fit\n    X, y = self._validate_input(X, y, incremental, reset=first_pass)\n  File \"/Users/Thomas/opt/anaconda3/envs/wild/lib/python3.9/site-packages/sklearn/neural_network/_multilayer_perceptron.py\", line 1597, in _validate_input\n    X, y = self._validate_data(\n  File \"/Users/Thomas/opt/anaconda3/envs/wild/lib/python3.9/site-packages/sklearn/base.py\", line 596, in _validate_data\n    X, y = check_X_y(X, y, **check_params)\n  File \"/Users/Thomas/opt/anaconda3/envs/wild/lib/python3.9/site-packages/sklearn/utils/validation.py\", line 1074, in check_X_y\n    X = check_array(\n  File \"/Users/Thomas/opt/anaconda3/envs/wild/lib/python3.9/site-packages/sklearn/utils/validation.py\", line 918, in check_array\n    raise ValueError(\nValueError: Found array with 0 feature(s) (shape=(189, 0)) while a minimum of 1 is required by MLPRegressor.\n\n--------------------------------------------------------------------------------\n1 fits failed with the following error:\nTraceback (most recent call last):\n  File \"/Users/Thomas/opt/anaconda3/envs/wild/lib/python3.9/site-packages/sklearn/model_selection/_validation.py\", line 686, in _fit_and_score\n    estimator.fit(X_train, y_train, **fit_params)\n  File \"/Users/Thomas/opt/anaconda3/envs/wild/lib/python3.9/site-packages/sklearn/pipeline.py\", line 382, in fit\n    self._final_estimator.fit(Xt, y, **fit_params_last_step)\n  File \"/Users/Thomas/opt/anaconda3/envs/wild/lib/python3.9/site-packages/sklearn/neural_network/_multilayer_perceptron.py\", line 762, in fit\n    return self._fit(X, y, incremental=False)\n  File \"/Users/Thomas/opt/anaconda3/envs/wild/lib/python3.9/site-packages/sklearn/neural_network/_multilayer_perceptron.py\", line 394, in _fit\n    X, y = self._validate_input(X, y, incremental, reset=first_pass)\n  File \"/Users/Thomas/opt/anaconda3/envs/wild/lib/python3.9/site-packages/sklearn/neural_network/_multilayer_perceptron.py\", line 1597, in _validate_input\n    X, y = self._validate_data(\n  File \"/Users/Thomas/opt/anaconda3/envs/wild/lib/python3.9/site-packages/sklearn/base.py\", line 596, in _validate_data\n    X, y = check_X_y(X, y, **check_params)\n  File \"/Users/Thomas/opt/anaconda3/envs/wild/lib/python3.9/site-packages/sklearn/utils/validation.py\", line 1074, in check_X_y\n    X = check_array(\n  File \"/Users/Thomas/opt/anaconda3/envs/wild/lib/python3.9/site-packages/sklearn/utils/validation.py\", line 918, in check_array\n    raise ValueError(\nValueError: Found array with 0 feature(s) (shape=(235, 0)) while a minimum of 1 is required by MLPRegressor.\n\n\n--------------------------------------------------------------------------------\n1 fits failed with the following error:\nTraceback (most recent call last):\n  File \"/Users/Thomas/opt/anaconda3/envs/wild/lib/python3.9/site-packages/sklearn/model_selection/_validation.py\", line 686, in _fit_and_score\n    estimator.fit(X_train, y_train, **fit_params)\n  File \"/Users/Thomas/opt/anaconda3/envs/wild/lib/python3.9/site-packages/sklearn/model_selection/_search.py\", line 875, in fit\n    self._run_search(evaluate_candidates)\n  File \"/Users/Thomas/opt/anaconda3/envs/wild/lib/python3.9/site-packages/sklearn/model_selection/_search.py\", line 1379, in _run_search\n    evaluate_candidates(ParameterGrid(self.param_grid))\n  File \"/Users/Thomas/opt/anaconda3/envs/wild/lib/python3.9/site-packages/sklearn/model_selection/_search.py\", line 852, in evaluate_candidates\n    _warn_or_raise_about_fit_failures(out, self.error_score)\n  File \"/Users/Thomas/opt/anaconda3/envs/wild/lib/python3.9/site-packages/sklearn/model_selection/_validation.py\", line 367, in _warn_or_raise_about_fit_failures\n    raise ValueError(all_fits_failed_message)\nValueError: \nAll the 5 fits failed.\nIt is very likely that your model is misconfigured.\nYou can try to debug the error by setting error_score='raise'.\n\nBelow are more details about the failures:\n--------------------------------------------------------------------------------\n1 fits failed with the following error:\nTraceback (most recent call last):\n  File \"/Users/Thomas/opt/anaconda3/envs/wild/lib/python3.9/site-packages/sklearn/model_selection/_validation.py\", line 686, in _fit_and_score\n    estimator.fit(X_train, y_train, **fit_params)\n  File \"/Users/Thomas/opt/anaconda3/envs/wild/lib/python3.9/site-packages/sklearn/pipeline.py\", line 382, in fit\n    self._final_estimator.fit(Xt, y, **fit_params_last_step)\n  File \"/Users/Thomas/opt/anaconda3/envs/wild/lib/python3.9/site-packages/sklearn/neural_network/_multilayer_perceptron.py\", line 762, in fit\n    return self._fit(X, y, incremental=False)\n  File \"/Users/Thomas/opt/anaconda3/envs/wild/lib/python3.9/site-packages/sklearn/neural_network/_multilayer_perceptron.py\", line 394, in _fit\n    X, y = self._validate_input(X, y, incremental, reset=first_pass)\n  File \"/Users/Thomas/opt/anaconda3/envs/wild/lib/python3.9/site-packages/sklearn/neural_network/_multilayer_perceptron.py\", line 1597, in _validate_input\n    X, y = self._validate_data(\n  File \"/Users/Thomas/opt/anaconda3/envs/wild/lib/python3.9/site-packages/sklearn/base.py\", line 596, in _validate_data\n    X, y = check_X_y(X, y, **check_params)\n  File \"/Users/Thomas/opt/anaconda3/envs/wild/lib/python3.9/site-packages/sklearn/utils/validation.py\", line 1074, in check_X_y\n    X = check_array(\n  File \"/Users/Thomas/opt/anaconda3/envs/wild/lib/python3.9/site-packages/sklearn/utils/validation.py\", line 918, in check_array\n    raise ValueError(\nValueError: Found array with 0 feature(s) (shape=(64, 0)) while a minimum of 1 is required by MLPRegressor.\n\n--------------------------------------------------------------------------------\n1 fits failed with the following error:\nTraceback (most recent call last):\n  File \"/Users/Thomas/opt/anaconda3/envs/wild/lib/python3.9/site-packages/sklearn/model_selection/_validation.py\", line 686, in _fit_and_score\n    estimator.fit(X_train, y_train, **fit_params)\n  File \"/Users/Thomas/opt/anaconda3/envs/wild/lib/python3.9/site-packages/sklearn/pipeline.py\", line 382, in fit\n    self._final_estimator.fit(Xt, y, **fit_params_last_step)\n  File \"/Users/Thomas/opt/anaconda3/envs/wild/lib/python3.9/site-packages/sklearn/neural_network/_multilayer_perceptron.py\", line 762, in fit\n    return self._fit(X, y, incremental=False)\n  File \"/Users/Thomas/opt/anaconda3/envs/wild/lib/python3.9/site-packages/sklearn/neural_network/_multilayer_perceptron.py\", line 394, in _fit\n    X, y = self._validate_input(X, y, incremental, reset=first_pass)\n  File \"/Users/Thomas/opt/anaconda3/envs/wild/lib/python3.9/site-packages/sklearn/neural_network/_multilayer_perceptron.py\", line 1597, in _validate_input\n    X, y = self._validate_data(\n  File \"/Users/Thomas/opt/anaconda3/envs/wild/lib/python3.9/site-packages/sklearn/base.py\", line 596, in _validate_data\n    X, y = check_X_y(X, y, **check_params)\n  File \"/Users/Thomas/opt/anaconda3/envs/wild/lib/python3.9/site-packages/sklearn/utils/validation.py\", line 1074, in check_X_y\n    X = check_array(\n  File \"/Users/Thomas/opt/anaconda3/envs/wild/lib/python3.9/site-packages/sklearn/utils/validation.py\", line 918, in check_array\n    raise ValueError(\nValueError: Found array with 0 feature(s) (shape=(126, 0)) while a minimum of 1 is required by MLPRegressor.\n\n--------------------------------------------------------------------------------\n1 fits failed with the following error:\nTraceback (most recent call last):\n  File \"/Users/Thomas/opt/anaconda3/envs/wild/lib/python3.9/site-packages/sklearn/model_selection/_validation.py\", line 686, in _fit_and_score\n    estimator.fit(X_train, y_train, **fit_params)\n  File \"/Users/Thomas/opt/anaconda3/envs/wild/lib/python3.9/site-packages/sklearn/pipeline.py\", line 382, in fit\n    self._final_estimator.fit(Xt, y, **fit_params_last_step)\n  File \"/Users/Thomas/opt/anaconda3/envs/wild/lib/python3.9/site-packages/sklearn/neural_network/_multilayer_perceptron.py\", line 762, in fit\n    return self._fit(X, y, incremental=False)\n  File \"/Users/Thomas/opt/anaconda3/envs/wild/lib/python3.9/site-packages/sklearn/neural_network/_multilayer_perceptron.py\", line 394, in _fit\n    X, y = self._validate_input(X, y, incremental, reset=first_pass)\n  File \"/Users/Thomas/opt/anaconda3/envs/wild/lib/python3.9/site-packages/sklearn/neural_network/_multilayer_perceptron.py\", line 1597, in _validate_input\n    X, y = self._validate_data(\n  File \"/Users/Thomas/opt/anaconda3/envs/wild/lib/python3.9/site-packages/sklearn/base.py\", line 596, in _validate_data\n    X, y = check_X_y(X, y, **check_params)\n  File \"/Users/Thomas/opt/anaconda3/envs/wild/lib/python3.9/site-packages/sklearn/utils/validation.py\", line 1074, in check_X_y\n    X = check_array(\n  File \"/Users/Thomas/opt/anaconda3/envs/wild/lib/python3.9/site-packages/sklearn/utils/validation.py\", line 918, in check_array\n    raise ValueError(\nValueError: Found array with 0 feature(s) (shape=(188, 0)) while a minimum of 1 is required by MLPRegressor.\n\n--------------------------------------------------------------------------------\n1 fits failed with the following error:\nTraceback (most recent call last):\n  File \"/Users/Thomas/opt/anaconda3/envs/wild/lib/python3.9/site-packages/sklearn/model_selection/_validation.py\", line 686, in _fit_and_score\n    estimator.fit(X_train, y_train, **fit_params)\n  File \"/Users/Thomas/opt/anaconda3/envs/wild/lib/python3.9/site-packages/sklearn/pipeline.py\", line 382, in fit\n    self._final_estimator.fit(Xt, y, **fit_params_last_step)\n  File \"/Users/Thomas/opt/anaconda3/envs/wild/lib/python3.9/site-packages/sklearn/neural_network/_multilayer_perceptron.py\", line 762, in fit\n    return self._fit(X, y, incremental=False)\n  File \"/Users/Thomas/opt/anaconda3/envs/wild/lib/python3.9/site-packages/sklearn/neural_network/_multilayer_perceptron.py\", line 394, in _fit\n    X, y = self._validate_input(X, y, incremental, reset=first_pass)\n  File \"/Users/Thomas/opt/anaconda3/envs/wild/lib/python3.9/site-packages/sklearn/neural_network/_multilayer_perceptron.py\", line 1597, in _validate_input\n    X, y = self._validate_data(\n  File \"/Users/Thomas/opt/anaconda3/envs/wild/lib/python3.9/site-packages/sklearn/base.py\", line 596, in _validate_data\n    X, y = check_X_y(X, y, **check_params)\n  File \"/Users/Thomas/opt/anaconda3/envs/wild/lib/python3.9/site-packages/sklearn/utils/validation.py\", line 1074, in check_X_y\n    X = check_array(\n  File \"/Users/Thomas/opt/anaconda3/envs/wild/lib/python3.9/site-packages/sklearn/utils/validation.py\", line 918, in check_array\n    raise ValueError(\nValueError: Found array with 0 feature(s) (shape=(250, 0)) while a minimum of 1 is required by MLPRegressor.\n\n--------------------------------------------------------------------------------\n1 fits failed with the following error:\nTraceback (most recent call last):\n  File \"/Users/Thomas/opt/anaconda3/envs/wild/lib/python3.9/site-packages/sklearn/model_selection/_validation.py\", line 686, in _fit_and_score\n    estimator.fit(X_train, y_train, **fit_params)\n  File \"/Users/Thomas/opt/anaconda3/envs/wild/lib/python3.9/site-packages/sklearn/pipeline.py\", line 382, in fit\n    self._final_estimator.fit(Xt, y, **fit_params_last_step)\n  File \"/Users/Thomas/opt/anaconda3/envs/wild/lib/python3.9/site-packages/sklearn/neural_network/_multilayer_perceptron.py\", line 762, in fit\n    return self._fit(X, y, incremental=False)\n  File \"/Users/Thomas/opt/anaconda3/envs/wild/lib/python3.9/site-packages/sklearn/neural_network/_multilayer_perceptron.py\", line 394, in _fit\n    X, y = self._validate_input(X, y, incremental, reset=first_pass)\n  File \"/Users/Thomas/opt/anaconda3/envs/wild/lib/python3.9/site-packages/sklearn/neural_network/_multilayer_perceptron.py\", line 1597, in _validate_input\n    X, y = self._validate_data(\n  File \"/Users/Thomas/opt/anaconda3/envs/wild/lib/python3.9/site-packages/sklearn/base.py\", line 596, in _validate_data\n    X, y = check_X_y(X, y, **check_params)\n  File \"/Users/Thomas/opt/anaconda3/envs/wild/lib/python3.9/site-packages/sklearn/utils/validation.py\", line 1074, in check_X_y\n    X = check_array(\n  File \"/Users/Thomas/opt/anaconda3/envs/wild/lib/python3.9/site-packages/sklearn/utils/validation.py\", line 918, in check_array\n    raise ValueError(\nValueError: Found array with 0 feature(s) (shape=(312, 0)) while a minimum of 1 is required by MLPRegressor.\n\n\n--------------------------------------------------------------------------------\n1 fits failed with the following error:\nTraceback (most recent call last):\n  File \"/Users/Thomas/opt/anaconda3/envs/wild/lib/python3.9/site-packages/sklearn/model_selection/_validation.py\", line 686, in _fit_and_score\n    estimator.fit(X_train, y_train, **fit_params)\n  File \"/Users/Thomas/opt/anaconda3/envs/wild/lib/python3.9/site-packages/sklearn/model_selection/_search.py\", line 875, in fit\n    self._run_search(evaluate_candidates)\n  File \"/Users/Thomas/opt/anaconda3/envs/wild/lib/python3.9/site-packages/sklearn/model_selection/_search.py\", line 1379, in _run_search\n    evaluate_candidates(ParameterGrid(self.param_grid))\n  File \"/Users/Thomas/opt/anaconda3/envs/wild/lib/python3.9/site-packages/sklearn/model_selection/_search.py\", line 852, in evaluate_candidates\n    _warn_or_raise_about_fit_failures(out, self.error_score)\n  File \"/Users/Thomas/opt/anaconda3/envs/wild/lib/python3.9/site-packages/sklearn/model_selection/_validation.py\", line 367, in _warn_or_raise_about_fit_failures\n    raise ValueError(all_fits_failed_message)\nValueError: \nAll the 5 fits failed.\nIt is very likely that your model is misconfigured.\nYou can try to debug the error by setting error_score='raise'.\n\nBelow are more details about the failures:\n--------------------------------------------------------------------------------\n1 fits failed with the following error:\nTraceback (most recent call last):\n  File \"/Users/Thomas/opt/anaconda3/envs/wild/lib/python3.9/site-packages/sklearn/model_selection/_validation.py\", line 686, in _fit_and_score\n    estimator.fit(X_train, y_train, **fit_params)\n  File \"/Users/Thomas/opt/anaconda3/envs/wild/lib/python3.9/site-packages/sklearn/pipeline.py\", line 382, in fit\n    self._final_estimator.fit(Xt, y, **fit_params_last_step)\n  File \"/Users/Thomas/opt/anaconda3/envs/wild/lib/python3.9/site-packages/sklearn/neural_network/_multilayer_perceptron.py\", line 762, in fit\n    return self._fit(X, y, incremental=False)\n  File \"/Users/Thomas/opt/anaconda3/envs/wild/lib/python3.9/site-packages/sklearn/neural_network/_multilayer_perceptron.py\", line 394, in _fit\n    X, y = self._validate_input(X, y, incremental, reset=first_pass)\n  File \"/Users/Thomas/opt/anaconda3/envs/wild/lib/python3.9/site-packages/sklearn/neural_network/_multilayer_perceptron.py\", line 1597, in _validate_input\n    X, y = self._validate_data(\n  File \"/Users/Thomas/opt/anaconda3/envs/wild/lib/python3.9/site-packages/sklearn/base.py\", line 596, in _validate_data\n    X, y = check_X_y(X, y, **check_params)\n  File \"/Users/Thomas/opt/anaconda3/envs/wild/lib/python3.9/site-packages/sklearn/utils/validation.py\", line 1074, in check_X_y\n    X = check_array(\n  File \"/Users/Thomas/opt/anaconda3/envs/wild/lib/python3.9/site-packages/sklearn/utils/validation.py\", line 918, in check_array\n    raise ValueError(\nValueError: Found array with 0 feature(s) (shape=(82, 0)) while a minimum of 1 is required by MLPRegressor.\n\n--------------------------------------------------------------------------------\n1 fits failed with the following error:\nTraceback (most recent call last):\n  File \"/Users/Thomas/opt/anaconda3/envs/wild/lib/python3.9/site-packages/sklearn/model_selection/_validation.py\", line 686, in _fit_and_score\n    estimator.fit(X_train, y_train, **fit_params)\n  File \"/Users/Thomas/opt/anaconda3/envs/wild/lib/python3.9/site-packages/sklearn/pipeline.py\", line 382, in fit\n    self._final_estimator.fit(Xt, y, **fit_params_last_step)\n  File \"/Users/Thomas/opt/anaconda3/envs/wild/lib/python3.9/site-packages/sklearn/neural_network/_multilayer_perceptron.py\", line 762, in fit\n    return self._fit(X, y, incremental=False)\n  File \"/Users/Thomas/opt/anaconda3/envs/wild/lib/python3.9/site-packages/sklearn/neural_network/_multilayer_perceptron.py\", line 394, in _fit\n    X, y = self._validate_input(X, y, incremental, reset=first_pass)\n  File \"/Users/Thomas/opt/anaconda3/envs/wild/lib/python3.9/site-packages/sklearn/neural_network/_multilayer_perceptron.py\", line 1597, in _validate_input\n    X, y = self._validate_data(\n  File \"/Users/Thomas/opt/anaconda3/envs/wild/lib/python3.9/site-packages/sklearn/base.py\", line 596, in _validate_data\n    X, y = check_X_y(X, y, **check_params)\n  File \"/Users/Thomas/opt/anaconda3/envs/wild/lib/python3.9/site-packages/sklearn/utils/validation.py\", line 1074, in check_X_y\n    X = check_array(\n  File \"/Users/Thomas/opt/anaconda3/envs/wild/lib/python3.9/site-packages/sklearn/utils/validation.py\", line 918, in check_array\n    raise ValueError(\nValueError: Found array with 0 feature(s) (shape=(159, 0)) while a minimum of 1 is required by MLPRegressor.\n\n--------------------------------------------------------------------------------\n1 fits failed with the following error:\nTraceback (most recent call last):\n  File \"/Users/Thomas/opt/anaconda3/envs/wild/lib/python3.9/site-packages/sklearn/model_selection/_validation.py\", line 686, in _fit_and_score\n    estimator.fit(X_train, y_train, **fit_params)\n  File \"/Users/Thomas/opt/anaconda3/envs/wild/lib/python3.9/site-packages/sklearn/pipeline.py\", line 382, in fit\n    self._final_estimator.fit(Xt, y, **fit_params_last_step)\n  File \"/Users/Thomas/opt/anaconda3/envs/wild/lib/python3.9/site-packages/sklearn/neural_network/_multilayer_perceptron.py\", line 762, in fit\n    return self._fit(X, y, incremental=False)\n  File \"/Users/Thomas/opt/anaconda3/envs/wild/lib/python3.9/site-packages/sklearn/neural_network/_multilayer_perceptron.py\", line 394, in _fit\n    X, y = self._validate_input(X, y, incremental, reset=first_pass)\n  File \"/Users/Thomas/opt/anaconda3/envs/wild/lib/python3.9/site-packages/sklearn/neural_network/_multilayer_perceptron.py\", line 1597, in _validate_input\n    X, y = self._validate_data(\n  File \"/Users/Thomas/opt/anaconda3/envs/wild/lib/python3.9/site-packages/sklearn/base.py\", line 596, in _validate_data\n    X, y = check_X_y(X, y, **check_params)\n  File \"/Users/Thomas/opt/anaconda3/envs/wild/lib/python3.9/site-packages/sklearn/utils/validation.py\", line 1074, in check_X_y\n    X = check_array(\n  File \"/Users/Thomas/opt/anaconda3/envs/wild/lib/python3.9/site-packages/sklearn/utils/validation.py\", line 918, in check_array\n    raise ValueError(\nValueError: Found array with 0 feature(s) (shape=(236, 0)) while a minimum of 1 is required by MLPRegressor.\n\n--------------------------------------------------------------------------------\n1 fits failed with the following error:\nTraceback (most recent call last):\n  File \"/Users/Thomas/opt/anaconda3/envs/wild/lib/python3.9/site-packages/sklearn/model_selection/_validation.py\", line 686, in _fit_and_score\n    estimator.fit(X_train, y_train, **fit_params)\n  File \"/Users/Thomas/opt/anaconda3/envs/wild/lib/python3.9/site-packages/sklearn/pipeline.py\", line 382, in fit\n    self._final_estimator.fit(Xt, y, **fit_params_last_step)\n  File \"/Users/Thomas/opt/anaconda3/envs/wild/lib/python3.9/site-packages/sklearn/neural_network/_multilayer_perceptron.py\", line 762, in fit\n    return self._fit(X, y, incremental=False)\n  File \"/Users/Thomas/opt/anaconda3/envs/wild/lib/python3.9/site-packages/sklearn/neural_network/_multilayer_perceptron.py\", line 394, in _fit\n    X, y = self._validate_input(X, y, incremental, reset=first_pass)\n  File \"/Users/Thomas/opt/anaconda3/envs/wild/lib/python3.9/site-packages/sklearn/neural_network/_multilayer_perceptron.py\", line 1597, in _validate_input\n    X, y = self._validate_data(\n  File \"/Users/Thomas/opt/anaconda3/envs/wild/lib/python3.9/site-packages/sklearn/base.py\", line 596, in _validate_data\n    X, y = check_X_y(X, y, **check_params)\n  File \"/Users/Thomas/opt/anaconda3/envs/wild/lib/python3.9/site-packages/sklearn/utils/validation.py\", line 1074, in check_X_y\n    X = check_array(\n  File \"/Users/Thomas/opt/anaconda3/envs/wild/lib/python3.9/site-packages/sklearn/utils/validation.py\", line 918, in check_array\n    raise ValueError(\nValueError: Found array with 0 feature(s) (shape=(313, 0)) while a minimum of 1 is required by MLPRegressor.\n\n--------------------------------------------------------------------------------\n1 fits failed with the following error:\nTraceback (most recent call last):\n  File \"/Users/Thomas/opt/anaconda3/envs/wild/lib/python3.9/site-packages/sklearn/model_selection/_validation.py\", line 686, in _fit_and_score\n    estimator.fit(X_train, y_train, **fit_params)\n  File \"/Users/Thomas/opt/anaconda3/envs/wild/lib/python3.9/site-packages/sklearn/pipeline.py\", line 382, in fit\n    self._final_estimator.fit(Xt, y, **fit_params_last_step)\n  File \"/Users/Thomas/opt/anaconda3/envs/wild/lib/python3.9/site-packages/sklearn/neural_network/_multilayer_perceptron.py\", line 762, in fit\n    return self._fit(X, y, incremental=False)\n  File \"/Users/Thomas/opt/anaconda3/envs/wild/lib/python3.9/site-packages/sklearn/neural_network/_multilayer_perceptron.py\", line 394, in _fit\n    X, y = self._validate_input(X, y, incremental, reset=first_pass)\n  File \"/Users/Thomas/opt/anaconda3/envs/wild/lib/python3.9/site-packages/sklearn/neural_network/_multilayer_perceptron.py\", line 1597, in _validate_input\n    X, y = self._validate_data(\n  File \"/Users/Thomas/opt/anaconda3/envs/wild/lib/python3.9/site-packages/sklearn/base.py\", line 596, in _validate_data\n    X, y = check_X_y(X, y, **check_params)\n  File \"/Users/Thomas/opt/anaconda3/envs/wild/lib/python3.9/site-packages/sklearn/utils/validation.py\", line 1074, in check_X_y\n    X = check_array(\n  File \"/Users/Thomas/opt/anaconda3/envs/wild/lib/python3.9/site-packages/sklearn/utils/validation.py\", line 918, in check_array\n    raise ValueError(\nValueError: Found array with 0 feature(s) (shape=(390, 0)) while a minimum of 1 is required by MLPRegressor.\n\n",
     "output_type": "error",
     "traceback": [
      "\u001b[0;31m---------------------------------------------------------------------------\u001b[0m",
      "\u001b[0;31mValueError\u001b[0m                                Traceback (most recent call last)",
      "\u001b[1;32m/Users/Thomas/Documents/GitHub/StatisticsProject/Linear_regressor copy.ipynb Cell 9\u001b[0m in \u001b[0;36m<cell line: 4>\u001b[0;34m()\u001b[0m\n\u001b[1;32m      <a href='vscode-notebook-cell:/Users/Thomas/Documents/GitHub/StatisticsProject/Linear_regressor%20copy.ipynb#X11sZmlsZQ%3D%3D?line=0'>1</a>\u001b[0m tscv \u001b[39m=\u001b[39m TimeSeriesSplit(n_splits\u001b[39m=\u001b[39m\u001b[39m5\u001b[39m)\n\u001b[1;32m      <a href='vscode-notebook-cell:/Users/Thomas/Documents/GitHub/StatisticsProject/Linear_regressor%20copy.ipynb#X11sZmlsZQ%3D%3D?line=1'>2</a>\u001b[0m pipeline \u001b[39m=\u001b[39m GridSearchCV(pipeline, param_grid\u001b[39m=\u001b[39mparameters, n_jobs\u001b[39m=\u001b[39m\u001b[39m15\u001b[39m, cv\u001b[39m=\u001b[39m tscv)\n\u001b[0;32m----> <a href='vscode-notebook-cell:/Users/Thomas/Documents/GitHub/StatisticsProject/Linear_regressor%20copy.ipynb#X11sZmlsZQ%3D%3D?line=3'>4</a>\u001b[0m pipeline\u001b[39m.\u001b[39;49mfit(train_X, np\u001b[39m.\u001b[39;49mravel(train_y))\n\u001b[1;32m      <a href='vscode-notebook-cell:/Users/Thomas/Documents/GitHub/StatisticsProject/Linear_regressor%20copy.ipynb#X11sZmlsZQ%3D%3D?line=5'>6</a>\u001b[0m bestParams \u001b[39m=\u001b[39m pipeline\u001b[39m.\u001b[39mbest_params_\n\u001b[1;32m      <a href='vscode-notebook-cell:/Users/Thomas/Documents/GitHub/StatisticsProject/Linear_regressor%20copy.ipynb#X11sZmlsZQ%3D%3D?line=7'>8</a>\u001b[0m predicted_qualities \u001b[39m=\u001b[39m pipeline\u001b[39m.\u001b[39mpredict(test_X)\n",
      "File \u001b[0;32m/Users/Thomas/opt/anaconda3/envs/wild/lib/python3.9/site-packages/sklearn/model_selection/_search.py:875\u001b[0m, in \u001b[0;36mBaseSearchCV.fit\u001b[0;34m(self, X, y, groups, **fit_params)\u001b[0m\n\u001b[1;32m    869\u001b[0m     results \u001b[39m=\u001b[39m \u001b[39mself\u001b[39m\u001b[39m.\u001b[39m_format_results(\n\u001b[1;32m    870\u001b[0m         all_candidate_params, n_splits, all_out, all_more_results\n\u001b[1;32m    871\u001b[0m     )\n\u001b[1;32m    873\u001b[0m     \u001b[39mreturn\u001b[39;00m results\n\u001b[0;32m--> 875\u001b[0m \u001b[39mself\u001b[39;49m\u001b[39m.\u001b[39;49m_run_search(evaluate_candidates)\n\u001b[1;32m    877\u001b[0m \u001b[39m# multimetric is determined here because in the case of a callable\u001b[39;00m\n\u001b[1;32m    878\u001b[0m \u001b[39m# self.scoring the return type is only known after calling\u001b[39;00m\n\u001b[1;32m    879\u001b[0m first_test_score \u001b[39m=\u001b[39m all_out[\u001b[39m0\u001b[39m][\u001b[39m\"\u001b[39m\u001b[39mtest_scores\u001b[39m\u001b[39m\"\u001b[39m]\n",
      "File \u001b[0;32m/Users/Thomas/opt/anaconda3/envs/wild/lib/python3.9/site-packages/sklearn/model_selection/_search.py:1379\u001b[0m, in \u001b[0;36mGridSearchCV._run_search\u001b[0;34m(self, evaluate_candidates)\u001b[0m\n\u001b[1;32m   1377\u001b[0m \u001b[39mdef\u001b[39;00m \u001b[39m_run_search\u001b[39m(\u001b[39mself\u001b[39m, evaluate_candidates):\n\u001b[1;32m   1378\u001b[0m     \u001b[39m\"\"\"Search all candidates in param_grid\"\"\"\u001b[39;00m\n\u001b[0;32m-> 1379\u001b[0m     evaluate_candidates(ParameterGrid(\u001b[39mself\u001b[39;49m\u001b[39m.\u001b[39;49mparam_grid))\n",
      "File \u001b[0;32m/Users/Thomas/opt/anaconda3/envs/wild/lib/python3.9/site-packages/sklearn/model_selection/_search.py:852\u001b[0m, in \u001b[0;36mBaseSearchCV.fit.<locals>.evaluate_candidates\u001b[0;34m(candidate_params, cv, more_results)\u001b[0m\n\u001b[1;32m    845\u001b[0m \u001b[39melif\u001b[39;00m \u001b[39mlen\u001b[39m(out) \u001b[39m!=\u001b[39m n_candidates \u001b[39m*\u001b[39m n_splits:\n\u001b[1;32m    846\u001b[0m     \u001b[39mraise\u001b[39;00m \u001b[39mValueError\u001b[39;00m(\n\u001b[1;32m    847\u001b[0m         \u001b[39m\"\u001b[39m\u001b[39mcv.split and cv.get_n_splits returned \u001b[39m\u001b[39m\"\u001b[39m\n\u001b[1;32m    848\u001b[0m         \u001b[39m\"\u001b[39m\u001b[39minconsistent results. Expected \u001b[39m\u001b[39m{}\u001b[39;00m\u001b[39m \u001b[39m\u001b[39m\"\u001b[39m\n\u001b[1;32m    849\u001b[0m         \u001b[39m\"\u001b[39m\u001b[39msplits, got \u001b[39m\u001b[39m{}\u001b[39;00m\u001b[39m\"\u001b[39m\u001b[39m.\u001b[39mformat(n_splits, \u001b[39mlen\u001b[39m(out) \u001b[39m/\u001b[39m\u001b[39m/\u001b[39m n_candidates)\n\u001b[1;32m    850\u001b[0m     )\n\u001b[0;32m--> 852\u001b[0m _warn_or_raise_about_fit_failures(out, \u001b[39mself\u001b[39;49m\u001b[39m.\u001b[39;49merror_score)\n\u001b[1;32m    854\u001b[0m \u001b[39m# For callable self.scoring, the return type is only know after\u001b[39;00m\n\u001b[1;32m    855\u001b[0m \u001b[39m# calling. If the return type is a dictionary, the error scores\u001b[39;00m\n\u001b[1;32m    856\u001b[0m \u001b[39m# can now be inserted with the correct key. The type checking\u001b[39;00m\n\u001b[1;32m    857\u001b[0m \u001b[39m# of out will be done in `_insert_error_scores`.\u001b[39;00m\n\u001b[1;32m    858\u001b[0m \u001b[39mif\u001b[39;00m callable(\u001b[39mself\u001b[39m\u001b[39m.\u001b[39mscoring):\n",
      "File \u001b[0;32m/Users/Thomas/opt/anaconda3/envs/wild/lib/python3.9/site-packages/sklearn/model_selection/_validation.py:367\u001b[0m, in \u001b[0;36m_warn_or_raise_about_fit_failures\u001b[0;34m(results, error_score)\u001b[0m\n\u001b[1;32m    360\u001b[0m \u001b[39mif\u001b[39;00m num_failed_fits \u001b[39m==\u001b[39m num_fits:\n\u001b[1;32m    361\u001b[0m     all_fits_failed_message \u001b[39m=\u001b[39m (\n\u001b[1;32m    362\u001b[0m         \u001b[39mf\u001b[39m\u001b[39m\"\u001b[39m\u001b[39m\\n\u001b[39;00m\u001b[39mAll the \u001b[39m\u001b[39m{\u001b[39;00mnum_fits\u001b[39m}\u001b[39;00m\u001b[39m fits failed.\u001b[39m\u001b[39m\\n\u001b[39;00m\u001b[39m\"\u001b[39m\n\u001b[1;32m    363\u001b[0m         \u001b[39m\"\u001b[39m\u001b[39mIt is very likely that your model is misconfigured.\u001b[39m\u001b[39m\\n\u001b[39;00m\u001b[39m\"\u001b[39m\n\u001b[1;32m    364\u001b[0m         \u001b[39m\"\u001b[39m\u001b[39mYou can try to debug the error by setting error_score=\u001b[39m\u001b[39m'\u001b[39m\u001b[39mraise\u001b[39m\u001b[39m'\u001b[39m\u001b[39m.\u001b[39m\u001b[39m\\n\u001b[39;00m\u001b[39m\\n\u001b[39;00m\u001b[39m\"\u001b[39m\n\u001b[1;32m    365\u001b[0m         \u001b[39mf\u001b[39m\u001b[39m\"\u001b[39m\u001b[39mBelow are more details about the failures:\u001b[39m\u001b[39m\\n\u001b[39;00m\u001b[39m{\u001b[39;00mfit_errors_summary\u001b[39m}\u001b[39;00m\u001b[39m\"\u001b[39m\n\u001b[1;32m    366\u001b[0m     )\n\u001b[0;32m--> 367\u001b[0m     \u001b[39mraise\u001b[39;00m \u001b[39mValueError\u001b[39;00m(all_fits_failed_message)\n\u001b[1;32m    369\u001b[0m \u001b[39melse\u001b[39;00m:\n\u001b[1;32m    370\u001b[0m     some_fits_failed_message \u001b[39m=\u001b[39m (\n\u001b[1;32m    371\u001b[0m         \u001b[39mf\u001b[39m\u001b[39m\"\u001b[39m\u001b[39m\\n\u001b[39;00m\u001b[39m{\u001b[39;00mnum_failed_fits\u001b[39m}\u001b[39;00m\u001b[39m fits failed out of a total of \u001b[39m\u001b[39m{\u001b[39;00mnum_fits\u001b[39m}\u001b[39;00m\u001b[39m.\u001b[39m\u001b[39m\\n\u001b[39;00m\u001b[39m\"\u001b[39m\n\u001b[1;32m    372\u001b[0m         \u001b[39m\"\u001b[39m\u001b[39mThe score on these train-test partitions for these parameters\u001b[39m\u001b[39m\"\u001b[39m\n\u001b[0;32m   (...)\u001b[0m\n\u001b[1;32m    376\u001b[0m         \u001b[39mf\u001b[39m\u001b[39m\"\u001b[39m\u001b[39mBelow are more details about the failures:\u001b[39m\u001b[39m\\n\u001b[39;00m\u001b[39m{\u001b[39;00mfit_errors_summary\u001b[39m}\u001b[39;00m\u001b[39m\"\u001b[39m\n\u001b[1;32m    377\u001b[0m     )\n",
      "\u001b[0;31mValueError\u001b[0m: \nAll the 5 fits failed.\nIt is very likely that your model is misconfigured.\nYou can try to debug the error by setting error_score='raise'.\n\nBelow are more details about the failures:\n--------------------------------------------------------------------------------\n1 fits failed with the following error:\nTraceback (most recent call last):\n  File \"/Users/Thomas/opt/anaconda3/envs/wild/lib/python3.9/site-packages/sklearn/model_selection/_validation.py\", line 686, in _fit_and_score\n    estimator.fit(X_train, y_train, **fit_params)\n  File \"/Users/Thomas/opt/anaconda3/envs/wild/lib/python3.9/site-packages/sklearn/model_selection/_search.py\", line 875, in fit\n    self._run_search(evaluate_candidates)\n  File \"/Users/Thomas/opt/anaconda3/envs/wild/lib/python3.9/site-packages/sklearn/model_selection/_search.py\", line 1379, in _run_search\n    evaluate_candidates(ParameterGrid(self.param_grid))\n  File \"/Users/Thomas/opt/anaconda3/envs/wild/lib/python3.9/site-packages/sklearn/model_selection/_search.py\", line 852, in evaluate_candidates\n    _warn_or_raise_about_fit_failures(out, self.error_score)\n  File \"/Users/Thomas/opt/anaconda3/envs/wild/lib/python3.9/site-packages/sklearn/model_selection/_validation.py\", line 367, in _warn_or_raise_about_fit_failures\n    raise ValueError(all_fits_failed_message)\nValueError: \nAll the 5 fits failed.\nIt is very likely that your model is misconfigured.\nYou can try to debug the error by setting error_score='raise'.\n\nBelow are more details about the failures:\n--------------------------------------------------------------------------------\n1 fits failed with the following error:\nTraceback (most recent call last):\n  File \"/Users/Thomas/opt/anaconda3/envs/wild/lib/python3.9/site-packages/sklearn/model_selection/_validation.py\", line 686, in _fit_and_score\n    estimator.fit(X_train, y_train, **fit_params)\n  File \"/Users/Thomas/opt/anaconda3/envs/wild/lib/python3.9/site-packages/sklearn/pipeline.py\", line 382, in fit\n    self._final_estimator.fit(Xt, y, **fit_params_last_step)\n  File \"/Users/Thomas/opt/anaconda3/envs/wild/lib/python3.9/site-packages/sklearn/neural_network/_multilayer_perceptron.py\", line 762, in fit\n    return self._fit(X, y, incremental=False)\n  File \"/Users/Thomas/opt/anaconda3/envs/wild/lib/python3.9/site-packages/sklearn/neural_network/_multilayer_perceptron.py\", line 394, in _fit\n    X, y = self._validate_input(X, y, incremental, reset=first_pass)\n  File \"/Users/Thomas/opt/anaconda3/envs/wild/lib/python3.9/site-packages/sklearn/neural_network/_multilayer_perceptron.py\", line 1597, in _validate_input\n    X, y = self._validate_data(\n  File \"/Users/Thomas/opt/anaconda3/envs/wild/lib/python3.9/site-packages/sklearn/base.py\", line 596, in _validate_data\n    X, y = check_X_y(X, y, **check_params)\n  File \"/Users/Thomas/opt/anaconda3/envs/wild/lib/python3.9/site-packages/sklearn/utils/validation.py\", line 1074, in check_X_y\n    X = check_array(\n  File \"/Users/Thomas/opt/anaconda3/envs/wild/lib/python3.9/site-packages/sklearn/utils/validation.py\", line 918, in check_array\n    raise ValueError(\nValueError: Found array with 0 feature(s) (shape=(20, 0)) while a minimum of 1 is required by MLPRegressor.\n\n--------------------------------------------------------------------------------\n1 fits failed with the following error:\nTraceback (most recent call last):\n  File \"/Users/Thomas/opt/anaconda3/envs/wild/lib/python3.9/site-packages/sklearn/model_selection/_validation.py\", line 686, in _fit_and_score\n    estimator.fit(X_train, y_train, **fit_params)\n  File \"/Users/Thomas/opt/anaconda3/envs/wild/lib/python3.9/site-packages/sklearn/pipeline.py\", line 382, in fit\n    self._final_estimator.fit(Xt, y, **fit_params_last_step)\n  File \"/Users/Thomas/opt/anaconda3/envs/wild/lib/python3.9/site-packages/sklearn/neural_network/_multilayer_perceptron.py\", line 762, in fit\n    return self._fit(X, y, incremental=False)\n  File \"/Users/Thomas/opt/anaconda3/envs/wild/lib/python3.9/site-packages/sklearn/neural_network/_multilayer_perceptron.py\", line 394, in _fit\n    X, y = self._validate_input(X, y, incremental, reset=first_pass)\n  File \"/Users/Thomas/opt/anaconda3/envs/wild/lib/python3.9/site-packages/sklearn/neural_network/_multilayer_perceptron.py\", line 1597, in _validate_input\n    X, y = self._validate_data(\n  File \"/Users/Thomas/opt/anaconda3/envs/wild/lib/python3.9/site-packages/sklearn/base.py\", line 596, in _validate_data\n    X, y = check_X_y(X, y, **check_params)\n  File \"/Users/Thomas/opt/anaconda3/envs/wild/lib/python3.9/site-packages/sklearn/utils/validation.py\", line 1074, in check_X_y\n    X = check_array(\n  File \"/Users/Thomas/opt/anaconda3/envs/wild/lib/python3.9/site-packages/sklearn/utils/validation.py\", line 918, in check_array\n    raise ValueError(\nValueError: Found array with 0 feature(s) (shape=(35, 0)) while a minimum of 1 is required by MLPRegressor.\n\n--------------------------------------------------------------------------------\n1 fits failed with the following error:\nTraceback (most recent call last):\n  File \"/Users/Thomas/opt/anaconda3/envs/wild/lib/python3.9/site-packages/sklearn/model_selection/_validation.py\", line 686, in _fit_and_score\n    estimator.fit(X_train, y_train, **fit_params)\n  File \"/Users/Thomas/opt/anaconda3/envs/wild/lib/python3.9/site-packages/sklearn/pipeline.py\", line 382, in fit\n    self._final_estimator.fit(Xt, y, **fit_params_last_step)\n  File \"/Users/Thomas/opt/anaconda3/envs/wild/lib/python3.9/site-packages/sklearn/neural_network/_multilayer_perceptron.py\", line 762, in fit\n    return self._fit(X, y, incremental=False)\n  File \"/Users/Thomas/opt/anaconda3/envs/wild/lib/python3.9/site-packages/sklearn/neural_network/_multilayer_perceptron.py\", line 394, in _fit\n    X, y = self._validate_input(X, y, incremental, reset=first_pass)\n  File \"/Users/Thomas/opt/anaconda3/envs/wild/lib/python3.9/site-packages/sklearn/neural_network/_multilayer_perceptron.py\", line 1597, in _validate_input\n    X, y = self._validate_data(\n  File \"/Users/Thomas/opt/anaconda3/envs/wild/lib/python3.9/site-packages/sklearn/base.py\", line 596, in _validate_data\n    X, y = check_X_y(X, y, **check_params)\n  File \"/Users/Thomas/opt/anaconda3/envs/wild/lib/python3.9/site-packages/sklearn/utils/validation.py\", line 1074, in check_X_y\n    X = check_array(\n  File \"/Users/Thomas/opt/anaconda3/envs/wild/lib/python3.9/site-packages/sklearn/utils/validation.py\", line 918, in check_array\n    raise ValueError(\nValueError: Found array with 0 feature(s) (shape=(50, 0)) while a minimum of 1 is required by MLPRegressor.\n\n--------------------------------------------------------------------------------\n1 fits failed with the following error:\nTraceback (most recent call last):\n  File \"/Users/Thomas/opt/anaconda3/envs/wild/lib/python3.9/site-packages/sklearn/model_selection/_validation.py\", line 686, in _fit_and_score\n    estimator.fit(X_train, y_train, **fit_params)\n  File \"/Users/Thomas/opt/anaconda3/envs/wild/lib/python3.9/site-packages/sklearn/pipeline.py\", line 382, in fit\n    self._final_estimator.fit(Xt, y, **fit_params_last_step)\n  File \"/Users/Thomas/opt/anaconda3/envs/wild/lib/python3.9/site-packages/sklearn/neural_network/_multilayer_perceptron.py\", line 762, in fit\n    return self._fit(X, y, incremental=False)\n  File \"/Users/Thomas/opt/anaconda3/envs/wild/lib/python3.9/site-packages/sklearn/neural_network/_multilayer_perceptron.py\", line 394, in _fit\n    X, y = self._validate_input(X, y, incremental, reset=first_pass)\n  File \"/Users/Thomas/opt/anaconda3/envs/wild/lib/python3.9/site-packages/sklearn/neural_network/_multilayer_perceptron.py\", line 1597, in _validate_input\n    X, y = self._validate_data(\n  File \"/Users/Thomas/opt/anaconda3/envs/wild/lib/python3.9/site-packages/sklearn/base.py\", line 596, in _validate_data\n    X, y = check_X_y(X, y, **check_params)\n  File \"/Users/Thomas/opt/anaconda3/envs/wild/lib/python3.9/site-packages/sklearn/utils/validation.py\", line 1074, in check_X_y\n    X = check_array(\n  File \"/Users/Thomas/opt/anaconda3/envs/wild/lib/python3.9/site-packages/sklearn/utils/validation.py\", line 918, in check_array\n    raise ValueError(\nValueError: Found array with 0 feature(s) (shape=(65, 0)) while a minimum of 1 is required by MLPRegressor.\n\n--------------------------------------------------------------------------------\n1 fits failed with the following error:\nTraceback (most recent call last):\n  File \"/Users/Thomas/opt/anaconda3/envs/wild/lib/python3.9/site-packages/sklearn/model_selection/_validation.py\", line 686, in _fit_and_score\n    estimator.fit(X_train, y_train, **fit_params)\n  File \"/Users/Thomas/opt/anaconda3/envs/wild/lib/python3.9/site-packages/sklearn/pipeline.py\", line 382, in fit\n    self._final_estimator.fit(Xt, y, **fit_params_last_step)\n  File \"/Users/Thomas/opt/anaconda3/envs/wild/lib/python3.9/site-packages/sklearn/neural_network/_multilayer_perceptron.py\", line 762, in fit\n    return self._fit(X, y, incremental=False)\n  File \"/Users/Thomas/opt/anaconda3/envs/wild/lib/python3.9/site-packages/sklearn/neural_network/_multilayer_perceptron.py\", line 394, in _fit\n    X, y = self._validate_input(X, y, incremental, reset=first_pass)\n  File \"/Users/Thomas/opt/anaconda3/envs/wild/lib/python3.9/site-packages/sklearn/neural_network/_multilayer_perceptron.py\", line 1597, in _validate_input\n    X, y = self._validate_data(\n  File \"/Users/Thomas/opt/anaconda3/envs/wild/lib/python3.9/site-packages/sklearn/base.py\", line 596, in _validate_data\n    X, y = check_X_y(X, y, **check_params)\n  File \"/Users/Thomas/opt/anaconda3/envs/wild/lib/python3.9/site-packages/sklearn/utils/validation.py\", line 1074, in check_X_y\n    X = check_array(\n  File \"/Users/Thomas/opt/anaconda3/envs/wild/lib/python3.9/site-packages/sklearn/utils/validation.py\", line 918, in check_array\n    raise ValueError(\nValueError: Found array with 0 feature(s) (shape=(80, 0)) while a minimum of 1 is required by MLPRegressor.\n\n\n--------------------------------------------------------------------------------\n1 fits failed with the following error:\nTraceback (most recent call last):\n  File \"/Users/Thomas/opt/anaconda3/envs/wild/lib/python3.9/site-packages/sklearn/model_selection/_validation.py\", line 686, in _fit_and_score\n    estimator.fit(X_train, y_train, **fit_params)\n  File \"/Users/Thomas/opt/anaconda3/envs/wild/lib/python3.9/site-packages/sklearn/model_selection/_search.py\", line 875, in fit\n    self._run_search(evaluate_candidates)\n  File \"/Users/Thomas/opt/anaconda3/envs/wild/lib/python3.9/site-packages/sklearn/model_selection/_search.py\", line 1379, in _run_search\n    evaluate_candidates(ParameterGrid(self.param_grid))\n  File \"/Users/Thomas/opt/anaconda3/envs/wild/lib/python3.9/site-packages/sklearn/model_selection/_search.py\", line 852, in evaluate_candidates\n    _warn_or_raise_about_fit_failures(out, self.error_score)\n  File \"/Users/Thomas/opt/anaconda3/envs/wild/lib/python3.9/site-packages/sklearn/model_selection/_validation.py\", line 367, in _warn_or_raise_about_fit_failures\n    raise ValueError(all_fits_failed_message)\nValueError: \nAll the 5 fits failed.\nIt is very likely that your model is misconfigured.\nYou can try to debug the error by setting error_score='raise'.\n\nBelow are more details about the failures:\n--------------------------------------------------------------------------------\n1 fits failed with the following error:\nTraceback (most recent call last):\n  File \"/Users/Thomas/opt/anaconda3/envs/wild/lib/python3.9/site-packages/sklearn/model_selection/_validation.py\", line 686, in _fit_and_score\n    estimator.fit(X_train, y_train, **fit_params)\n  File \"/Users/Thomas/opt/anaconda3/envs/wild/lib/python3.9/site-packages/sklearn/pipeline.py\", line 382, in fit\n    self._final_estimator.fit(Xt, y, **fit_params_last_step)\n  File \"/Users/Thomas/opt/anaconda3/envs/wild/lib/python3.9/site-packages/sklearn/neural_network/_multilayer_perceptron.py\", line 762, in fit\n    return self._fit(X, y, incremental=False)\n  File \"/Users/Thomas/opt/anaconda3/envs/wild/lib/python3.9/site-packages/sklearn/neural_network/_multilayer_perceptron.py\", line 394, in _fit\n    X, y = self._validate_input(X, y, incremental, reset=first_pass)\n  File \"/Users/Thomas/opt/anaconda3/envs/wild/lib/python3.9/site-packages/sklearn/neural_network/_multilayer_perceptron.py\", line 1597, in _validate_input\n    X, y = self._validate_data(\n  File \"/Users/Thomas/opt/anaconda3/envs/wild/lib/python3.9/site-packages/sklearn/base.py\", line 596, in _validate_data\n    X, y = check_X_y(X, y, **check_params)\n  File \"/Users/Thomas/opt/anaconda3/envs/wild/lib/python3.9/site-packages/sklearn/utils/validation.py\", line 1074, in check_X_y\n    X = check_array(\n  File \"/Users/Thomas/opt/anaconda3/envs/wild/lib/python3.9/site-packages/sklearn/utils/validation.py\", line 918, in check_array\n    raise ValueError(\nValueError: Found array with 0 feature(s) (shape=(33, 0)) while a minimum of 1 is required by MLPRegressor.\n\n--------------------------------------------------------------------------------\n1 fits failed with the following error:\nTraceback (most recent call last):\n  File \"/Users/Thomas/opt/anaconda3/envs/wild/lib/python3.9/site-packages/sklearn/model_selection/_validation.py\", line 686, in _fit_and_score\n    estimator.fit(X_train, y_train, **fit_params)\n  File \"/Users/Thomas/opt/anaconda3/envs/wild/lib/python3.9/site-packages/sklearn/pipeline.py\", line 382, in fit\n    self._final_estimator.fit(Xt, y, **fit_params_last_step)\n  File \"/Users/Thomas/opt/anaconda3/envs/wild/lib/python3.9/site-packages/sklearn/neural_network/_multilayer_perceptron.py\", line 762, in fit\n    return self._fit(X, y, incremental=False)\n  File \"/Users/Thomas/opt/anaconda3/envs/wild/lib/python3.9/site-packages/sklearn/neural_network/_multilayer_perceptron.py\", line 394, in _fit\n    X, y = self._validate_input(X, y, incremental, reset=first_pass)\n  File \"/Users/Thomas/opt/anaconda3/envs/wild/lib/python3.9/site-packages/sklearn/neural_network/_multilayer_perceptron.py\", line 1597, in _validate_input\n    X, y = self._validate_data(\n  File \"/Users/Thomas/opt/anaconda3/envs/wild/lib/python3.9/site-packages/sklearn/base.py\", line 596, in _validate_data\n    X, y = check_X_y(X, y, **check_params)\n  File \"/Users/Thomas/opt/anaconda3/envs/wild/lib/python3.9/site-packages/sklearn/utils/validation.py\", line 1074, in check_X_y\n    X = check_array(\n  File \"/Users/Thomas/opt/anaconda3/envs/wild/lib/python3.9/site-packages/sklearn/utils/validation.py\", line 918, in check_array\n    raise ValueError(\nValueError: Found array with 0 feature(s) (shape=(64, 0)) while a minimum of 1 is required by MLPRegressor.\n\n--------------------------------------------------------------------------------\n1 fits failed with the following error:\nTraceback (most recent call last):\n  File \"/Users/Thomas/opt/anaconda3/envs/wild/lib/python3.9/site-packages/sklearn/model_selection/_validation.py\", line 686, in _fit_and_score\n    estimator.fit(X_train, y_train, **fit_params)\n  File \"/Users/Thomas/opt/anaconda3/envs/wild/lib/python3.9/site-packages/sklearn/pipeline.py\", line 382, in fit\n    self._final_estimator.fit(Xt, y, **fit_params_last_step)\n  File \"/Users/Thomas/opt/anaconda3/envs/wild/lib/python3.9/site-packages/sklearn/neural_network/_multilayer_perceptron.py\", line 762, in fit\n    return self._fit(X, y, incremental=False)\n  File \"/Users/Thomas/opt/anaconda3/envs/wild/lib/python3.9/site-packages/sklearn/neural_network/_multilayer_perceptron.py\", line 394, in _fit\n    X, y = self._validate_input(X, y, incremental, reset=first_pass)\n  File \"/Users/Thomas/opt/anaconda3/envs/wild/lib/python3.9/site-packages/sklearn/neural_network/_multilayer_perceptron.py\", line 1597, in _validate_input\n    X, y = self._validate_data(\n  File \"/Users/Thomas/opt/anaconda3/envs/wild/lib/python3.9/site-packages/sklearn/base.py\", line 596, in _validate_data\n    X, y = check_X_y(X, y, **check_params)\n  File \"/Users/Thomas/opt/anaconda3/envs/wild/lib/python3.9/site-packages/sklearn/utils/validation.py\", line 1074, in check_X_y\n    X = check_array(\n  File \"/Users/Thomas/opt/anaconda3/envs/wild/lib/python3.9/site-packages/sklearn/utils/validation.py\", line 918, in check_array\n    raise ValueError(\nValueError: Found array with 0 feature(s) (shape=(95, 0)) while a minimum of 1 is required by MLPRegressor.\n\n--------------------------------------------------------------------------------\n1 fits failed with the following error:\nTraceback (most recent call last):\n  File \"/Users/Thomas/opt/anaconda3/envs/wild/lib/python3.9/site-packages/sklearn/model_selection/_validation.py\", line 686, in _fit_and_score\n    estimator.fit(X_train, y_train, **fit_params)\n  File \"/Users/Thomas/opt/anaconda3/envs/wild/lib/python3.9/site-packages/sklearn/pipeline.py\", line 382, in fit\n    self._final_estimator.fit(Xt, y, **fit_params_last_step)\n  File \"/Users/Thomas/opt/anaconda3/envs/wild/lib/python3.9/site-packages/sklearn/neural_network/_multilayer_perceptron.py\", line 762, in fit\n    return self._fit(X, y, incremental=False)\n  File \"/Users/Thomas/opt/anaconda3/envs/wild/lib/python3.9/site-packages/sklearn/neural_network/_multilayer_perceptron.py\", line 394, in _fit\n    X, y = self._validate_input(X, y, incremental, reset=first_pass)\n  File \"/Users/Thomas/opt/anaconda3/envs/wild/lib/python3.9/site-packages/sklearn/neural_network/_multilayer_perceptron.py\", line 1597, in _validate_input\n    X, y = self._validate_data(\n  File \"/Users/Thomas/opt/anaconda3/envs/wild/lib/python3.9/site-packages/sklearn/base.py\", line 596, in _validate_data\n    X, y = check_X_y(X, y, **check_params)\n  File \"/Users/Thomas/opt/anaconda3/envs/wild/lib/python3.9/site-packages/sklearn/utils/validation.py\", line 1074, in check_X_y\n    X = check_array(\n  File \"/Users/Thomas/opt/anaconda3/envs/wild/lib/python3.9/site-packages/sklearn/utils/validation.py\", line 918, in check_array\n    raise ValueError(\nValueError: Found array with 0 feature(s) (shape=(126, 0)) while a minimum of 1 is required by MLPRegressor.\n\n--------------------------------------------------------------------------------\n1 fits failed with the following error:\nTraceback (most recent call last):\n  File \"/Users/Thomas/opt/anaconda3/envs/wild/lib/python3.9/site-packages/sklearn/model_selection/_validation.py\", line 686, in _fit_and_score\n    estimator.fit(X_train, y_train, **fit_params)\n  File \"/Users/Thomas/opt/anaconda3/envs/wild/lib/python3.9/site-packages/sklearn/pipeline.py\", line 382, in fit\n    self._final_estimator.fit(Xt, y, **fit_params_last_step)\n  File \"/Users/Thomas/opt/anaconda3/envs/wild/lib/python3.9/site-packages/sklearn/neural_network/_multilayer_perceptron.py\", line 762, in fit\n    return self._fit(X, y, incremental=False)\n  File \"/Users/Thomas/opt/anaconda3/envs/wild/lib/python3.9/site-packages/sklearn/neural_network/_multilayer_perceptron.py\", line 394, in _fit\n    X, y = self._validate_input(X, y, incremental, reset=first_pass)\n  File \"/Users/Thomas/opt/anaconda3/envs/wild/lib/python3.9/site-packages/sklearn/neural_network/_multilayer_perceptron.py\", line 1597, in _validate_input\n    X, y = self._validate_data(\n  File \"/Users/Thomas/opt/anaconda3/envs/wild/lib/python3.9/site-packages/sklearn/base.py\", line 596, in _validate_data\n    X, y = check_X_y(X, y, **check_params)\n  File \"/Users/Thomas/opt/anaconda3/envs/wild/lib/python3.9/site-packages/sklearn/utils/validation.py\", line 1074, in check_X_y\n    X = check_array(\n  File \"/Users/Thomas/opt/anaconda3/envs/wild/lib/python3.9/site-packages/sklearn/utils/validation.py\", line 918, in check_array\n    raise ValueError(\nValueError: Found array with 0 feature(s) (shape=(157, 0)) while a minimum of 1 is required by MLPRegressor.\n\n\n--------------------------------------------------------------------------------\n1 fits failed with the following error:\nTraceback (most recent call last):\n  File \"/Users/Thomas/opt/anaconda3/envs/wild/lib/python3.9/site-packages/sklearn/model_selection/_validation.py\", line 686, in _fit_and_score\n    estimator.fit(X_train, y_train, **fit_params)\n  File \"/Users/Thomas/opt/anaconda3/envs/wild/lib/python3.9/site-packages/sklearn/model_selection/_search.py\", line 875, in fit\n    self._run_search(evaluate_candidates)\n  File \"/Users/Thomas/opt/anaconda3/envs/wild/lib/python3.9/site-packages/sklearn/model_selection/_search.py\", line 1379, in _run_search\n    evaluate_candidates(ParameterGrid(self.param_grid))\n  File \"/Users/Thomas/opt/anaconda3/envs/wild/lib/python3.9/site-packages/sklearn/model_selection/_search.py\", line 852, in evaluate_candidates\n    _warn_or_raise_about_fit_failures(out, self.error_score)\n  File \"/Users/Thomas/opt/anaconda3/envs/wild/lib/python3.9/site-packages/sklearn/model_selection/_validation.py\", line 367, in _warn_or_raise_about_fit_failures\n    raise ValueError(all_fits_failed_message)\nValueError: \nAll the 5 fits failed.\nIt is very likely that your model is misconfigured.\nYou can try to debug the error by setting error_score='raise'.\n\nBelow are more details about the failures:\n--------------------------------------------------------------------------------\n1 fits failed with the following error:\nTraceback (most recent call last):\n  File \"/Users/Thomas/opt/anaconda3/envs/wild/lib/python3.9/site-packages/sklearn/model_selection/_validation.py\", line 686, in _fit_and_score\n    estimator.fit(X_train, y_train, **fit_params)\n  File \"/Users/Thomas/opt/anaconda3/envs/wild/lib/python3.9/site-packages/sklearn/pipeline.py\", line 382, in fit\n    self._final_estimator.fit(Xt, y, **fit_params_last_step)\n  File \"/Users/Thomas/opt/anaconda3/envs/wild/lib/python3.9/site-packages/sklearn/neural_network/_multilayer_perceptron.py\", line 762, in fit\n    return self._fit(X, y, incremental=False)\n  File \"/Users/Thomas/opt/anaconda3/envs/wild/lib/python3.9/site-packages/sklearn/neural_network/_multilayer_perceptron.py\", line 394, in _fit\n    X, y = self._validate_input(X, y, incremental, reset=first_pass)\n  File \"/Users/Thomas/opt/anaconda3/envs/wild/lib/python3.9/site-packages/sklearn/neural_network/_multilayer_perceptron.py\", line 1597, in _validate_input\n    X, y = self._validate_data(\n  File \"/Users/Thomas/opt/anaconda3/envs/wild/lib/python3.9/site-packages/sklearn/base.py\", line 596, in _validate_data\n    X, y = check_X_y(X, y, **check_params)\n  File \"/Users/Thomas/opt/anaconda3/envs/wild/lib/python3.9/site-packages/sklearn/utils/validation.py\", line 1074, in check_X_y\n    X = check_array(\n  File \"/Users/Thomas/opt/anaconda3/envs/wild/lib/python3.9/site-packages/sklearn/utils/validation.py\", line 918, in check_array\n    raise ValueError(\nValueError: Found array with 0 feature(s) (shape=(51, 0)) while a minimum of 1 is required by MLPRegressor.\n\n--------------------------------------------------------------------------------\n1 fits failed with the following error:\nTraceback (most recent call last):\n  File \"/Users/Thomas/opt/anaconda3/envs/wild/lib/python3.9/site-packages/sklearn/model_selection/_validation.py\", line 686, in _fit_and_score\n    estimator.fit(X_train, y_train, **fit_params)\n  File \"/Users/Thomas/opt/anaconda3/envs/wild/lib/python3.9/site-packages/sklearn/pipeline.py\", line 382, in fit\n    self._final_estimator.fit(Xt, y, **fit_params_last_step)\n  File \"/Users/Thomas/opt/anaconda3/envs/wild/lib/python3.9/site-packages/sklearn/neural_network/_multilayer_perceptron.py\", line 762, in fit\n    return self._fit(X, y, incremental=False)\n  File \"/Users/Thomas/opt/anaconda3/envs/wild/lib/python3.9/site-packages/sklearn/neural_network/_multilayer_perceptron.py\", line 394, in _fit\n    X, y = self._validate_input(X, y, incremental, reset=first_pass)\n  File \"/Users/Thomas/opt/anaconda3/envs/wild/lib/python3.9/site-packages/sklearn/neural_network/_multilayer_perceptron.py\", line 1597, in _validate_input\n    X, y = self._validate_data(\n  File \"/Users/Thomas/opt/anaconda3/envs/wild/lib/python3.9/site-packages/sklearn/base.py\", line 596, in _validate_data\n    X, y = check_X_y(X, y, **check_params)\n  File \"/Users/Thomas/opt/anaconda3/envs/wild/lib/python3.9/site-packages/sklearn/utils/validation.py\", line 1074, in check_X_y\n    X = check_array(\n  File \"/Users/Thomas/opt/anaconda3/envs/wild/lib/python3.9/site-packages/sklearn/utils/validation.py\", line 918, in check_array\n    raise ValueError(\nValueError: Found array with 0 feature(s) (shape=(97, 0)) while a minimum of 1 is required by MLPRegressor.\n\n--------------------------------------------------------------------------------\n1 fits failed with the following error:\nTraceback (most recent call last):\n  File \"/Users/Thomas/opt/anaconda3/envs/wild/lib/python3.9/site-packages/sklearn/model_selection/_validation.py\", line 686, in _fit_and_score\n    estimator.fit(X_train, y_train, **fit_params)\n  File \"/Users/Thomas/opt/anaconda3/envs/wild/lib/python3.9/site-packages/sklearn/pipeline.py\", line 382, in fit\n    self._final_estimator.fit(Xt, y, **fit_params_last_step)\n  File \"/Users/Thomas/opt/anaconda3/envs/wild/lib/python3.9/site-packages/sklearn/neural_network/_multilayer_perceptron.py\", line 762, in fit\n    return self._fit(X, y, incremental=False)\n  File \"/Users/Thomas/opt/anaconda3/envs/wild/lib/python3.9/site-packages/sklearn/neural_network/_multilayer_perceptron.py\", line 394, in _fit\n    X, y = self._validate_input(X, y, incremental, reset=first_pass)\n  File \"/Users/Thomas/opt/anaconda3/envs/wild/lib/python3.9/site-packages/sklearn/neural_network/_multilayer_perceptron.py\", line 1597, in _validate_input\n    X, y = self._validate_data(\n  File \"/Users/Thomas/opt/anaconda3/envs/wild/lib/python3.9/site-packages/sklearn/base.py\", line 596, in _validate_data\n    X, y = check_X_y(X, y, **check_params)\n  File \"/Users/Thomas/opt/anaconda3/envs/wild/lib/python3.9/site-packages/sklearn/utils/validation.py\", line 1074, in check_X_y\n    X = check_array(\n  File \"/Users/Thomas/opt/anaconda3/envs/wild/lib/python3.9/site-packages/sklearn/utils/validation.py\", line 918, in check_array\n    raise ValueError(\nValueError: Found array with 0 feature(s) (shape=(143, 0)) while a minimum of 1 is required by MLPRegressor.\n\n--------------------------------------------------------------------------------\n1 fits failed with the following error:\nTraceback (most recent call last):\n  File \"/Users/Thomas/opt/anaconda3/envs/wild/lib/python3.9/site-packages/sklearn/model_selection/_validation.py\", line 686, in _fit_and_score\n    estimator.fit(X_train, y_train, **fit_params)\n  File \"/Users/Thomas/opt/anaconda3/envs/wild/lib/python3.9/site-packages/sklearn/pipeline.py\", line 382, in fit\n    self._final_estimator.fit(Xt, y, **fit_params_last_step)\n  File \"/Users/Thomas/opt/anaconda3/envs/wild/lib/python3.9/site-packages/sklearn/neural_network/_multilayer_perceptron.py\", line 762, in fit\n    return self._fit(X, y, incremental=False)\n  File \"/Users/Thomas/opt/anaconda3/envs/wild/lib/python3.9/site-packages/sklearn/neural_network/_multilayer_perceptron.py\", line 394, in _fit\n    X, y = self._validate_input(X, y, incremental, reset=first_pass)\n  File \"/Users/Thomas/opt/anaconda3/envs/wild/lib/python3.9/site-packages/sklearn/neural_network/_multilayer_perceptron.py\", line 1597, in _validate_input\n    X, y = self._validate_data(\n  File \"/Users/Thomas/opt/anaconda3/envs/wild/lib/python3.9/site-packages/sklearn/base.py\", line 596, in _validate_data\n    X, y = check_X_y(X, y, **check_params)\n  File \"/Users/Thomas/opt/anaconda3/envs/wild/lib/python3.9/site-packages/sklearn/utils/validation.py\", line 1074, in check_X_y\n    X = check_array(\n  File \"/Users/Thomas/opt/anaconda3/envs/wild/lib/python3.9/site-packages/sklearn/utils/validation.py\", line 918, in check_array\n    raise ValueError(\nValueError: Found array with 0 feature(s) (shape=(189, 0)) while a minimum of 1 is required by MLPRegressor.\n\n--------------------------------------------------------------------------------\n1 fits failed with the following error:\nTraceback (most recent call last):\n  File \"/Users/Thomas/opt/anaconda3/envs/wild/lib/python3.9/site-packages/sklearn/model_selection/_validation.py\", line 686, in _fit_and_score\n    estimator.fit(X_train, y_train, **fit_params)\n  File \"/Users/Thomas/opt/anaconda3/envs/wild/lib/python3.9/site-packages/sklearn/pipeline.py\", line 382, in fit\n    self._final_estimator.fit(Xt, y, **fit_params_last_step)\n  File \"/Users/Thomas/opt/anaconda3/envs/wild/lib/python3.9/site-packages/sklearn/neural_network/_multilayer_perceptron.py\", line 762, in fit\n    return self._fit(X, y, incremental=False)\n  File \"/Users/Thomas/opt/anaconda3/envs/wild/lib/python3.9/site-packages/sklearn/neural_network/_multilayer_perceptron.py\", line 394, in _fit\n    X, y = self._validate_input(X, y, incremental, reset=first_pass)\n  File \"/Users/Thomas/opt/anaconda3/envs/wild/lib/python3.9/site-packages/sklearn/neural_network/_multilayer_perceptron.py\", line 1597, in _validate_input\n    X, y = self._validate_data(\n  File \"/Users/Thomas/opt/anaconda3/envs/wild/lib/python3.9/site-packages/sklearn/base.py\", line 596, in _validate_data\n    X, y = check_X_y(X, y, **check_params)\n  File \"/Users/Thomas/opt/anaconda3/envs/wild/lib/python3.9/site-packages/sklearn/utils/validation.py\", line 1074, in check_X_y\n    X = check_array(\n  File \"/Users/Thomas/opt/anaconda3/envs/wild/lib/python3.9/site-packages/sklearn/utils/validation.py\", line 918, in check_array\n    raise ValueError(\nValueError: Found array with 0 feature(s) (shape=(235, 0)) while a minimum of 1 is required by MLPRegressor.\n\n\n--------------------------------------------------------------------------------\n1 fits failed with the following error:\nTraceback (most recent call last):\n  File \"/Users/Thomas/opt/anaconda3/envs/wild/lib/python3.9/site-packages/sklearn/model_selection/_validation.py\", line 686, in _fit_and_score\n    estimator.fit(X_train, y_train, **fit_params)\n  File \"/Users/Thomas/opt/anaconda3/envs/wild/lib/python3.9/site-packages/sklearn/model_selection/_search.py\", line 875, in fit\n    self._run_search(evaluate_candidates)\n  File \"/Users/Thomas/opt/anaconda3/envs/wild/lib/python3.9/site-packages/sklearn/model_selection/_search.py\", line 1379, in _run_search\n    evaluate_candidates(ParameterGrid(self.param_grid))\n  File \"/Users/Thomas/opt/anaconda3/envs/wild/lib/python3.9/site-packages/sklearn/model_selection/_search.py\", line 852, in evaluate_candidates\n    _warn_or_raise_about_fit_failures(out, self.error_score)\n  File \"/Users/Thomas/opt/anaconda3/envs/wild/lib/python3.9/site-packages/sklearn/model_selection/_validation.py\", line 367, in _warn_or_raise_about_fit_failures\n    raise ValueError(all_fits_failed_message)\nValueError: \nAll the 5 fits failed.\nIt is very likely that your model is misconfigured.\nYou can try to debug the error by setting error_score='raise'.\n\nBelow are more details about the failures:\n--------------------------------------------------------------------------------\n1 fits failed with the following error:\nTraceback (most recent call last):\n  File \"/Users/Thomas/opt/anaconda3/envs/wild/lib/python3.9/site-packages/sklearn/model_selection/_validation.py\", line 686, in _fit_and_score\n    estimator.fit(X_train, y_train, **fit_params)\n  File \"/Users/Thomas/opt/anaconda3/envs/wild/lib/python3.9/site-packages/sklearn/pipeline.py\", line 382, in fit\n    self._final_estimator.fit(Xt, y, **fit_params_last_step)\n  File \"/Users/Thomas/opt/anaconda3/envs/wild/lib/python3.9/site-packages/sklearn/neural_network/_multilayer_perceptron.py\", line 762, in fit\n    return self._fit(X, y, incremental=False)\n  File \"/Users/Thomas/opt/anaconda3/envs/wild/lib/python3.9/site-packages/sklearn/neural_network/_multilayer_perceptron.py\", line 394, in _fit\n    X, y = self._validate_input(X, y, incremental, reset=first_pass)\n  File \"/Users/Thomas/opt/anaconda3/envs/wild/lib/python3.9/site-packages/sklearn/neural_network/_multilayer_perceptron.py\", line 1597, in _validate_input\n    X, y = self._validate_data(\n  File \"/Users/Thomas/opt/anaconda3/envs/wild/lib/python3.9/site-packages/sklearn/base.py\", line 596, in _validate_data\n    X, y = check_X_y(X, y, **check_params)\n  File \"/Users/Thomas/opt/anaconda3/envs/wild/lib/python3.9/site-packages/sklearn/utils/validation.py\", line 1074, in check_X_y\n    X = check_array(\n  File \"/Users/Thomas/opt/anaconda3/envs/wild/lib/python3.9/site-packages/sklearn/utils/validation.py\", line 918, in check_array\n    raise ValueError(\nValueError: Found array with 0 feature(s) (shape=(64, 0)) while a minimum of 1 is required by MLPRegressor.\n\n--------------------------------------------------------------------------------\n1 fits failed with the following error:\nTraceback (most recent call last):\n  File \"/Users/Thomas/opt/anaconda3/envs/wild/lib/python3.9/site-packages/sklearn/model_selection/_validation.py\", line 686, in _fit_and_score\n    estimator.fit(X_train, y_train, **fit_params)\n  File \"/Users/Thomas/opt/anaconda3/envs/wild/lib/python3.9/site-packages/sklearn/pipeline.py\", line 382, in fit\n    self._final_estimator.fit(Xt, y, **fit_params_last_step)\n  File \"/Users/Thomas/opt/anaconda3/envs/wild/lib/python3.9/site-packages/sklearn/neural_network/_multilayer_perceptron.py\", line 762, in fit\n    return self._fit(X, y, incremental=False)\n  File \"/Users/Thomas/opt/anaconda3/envs/wild/lib/python3.9/site-packages/sklearn/neural_network/_multilayer_perceptron.py\", line 394, in _fit\n    X, y = self._validate_input(X, y, incremental, reset=first_pass)\n  File \"/Users/Thomas/opt/anaconda3/envs/wild/lib/python3.9/site-packages/sklearn/neural_network/_multilayer_perceptron.py\", line 1597, in _validate_input\n    X, y = self._validate_data(\n  File \"/Users/Thomas/opt/anaconda3/envs/wild/lib/python3.9/site-packages/sklearn/base.py\", line 596, in _validate_data\n    X, y = check_X_y(X, y, **check_params)\n  File \"/Users/Thomas/opt/anaconda3/envs/wild/lib/python3.9/site-packages/sklearn/utils/validation.py\", line 1074, in check_X_y\n    X = check_array(\n  File \"/Users/Thomas/opt/anaconda3/envs/wild/lib/python3.9/site-packages/sklearn/utils/validation.py\", line 918, in check_array\n    raise ValueError(\nValueError: Found array with 0 feature(s) (shape=(126, 0)) while a minimum of 1 is required by MLPRegressor.\n\n--------------------------------------------------------------------------------\n1 fits failed with the following error:\nTraceback (most recent call last):\n  File \"/Users/Thomas/opt/anaconda3/envs/wild/lib/python3.9/site-packages/sklearn/model_selection/_validation.py\", line 686, in _fit_and_score\n    estimator.fit(X_train, y_train, **fit_params)\n  File \"/Users/Thomas/opt/anaconda3/envs/wild/lib/python3.9/site-packages/sklearn/pipeline.py\", line 382, in fit\n    self._final_estimator.fit(Xt, y, **fit_params_last_step)\n  File \"/Users/Thomas/opt/anaconda3/envs/wild/lib/python3.9/site-packages/sklearn/neural_network/_multilayer_perceptron.py\", line 762, in fit\n    return self._fit(X, y, incremental=False)\n  File \"/Users/Thomas/opt/anaconda3/envs/wild/lib/python3.9/site-packages/sklearn/neural_network/_multilayer_perceptron.py\", line 394, in _fit\n    X, y = self._validate_input(X, y, incremental, reset=first_pass)\n  File \"/Users/Thomas/opt/anaconda3/envs/wild/lib/python3.9/site-packages/sklearn/neural_network/_multilayer_perceptron.py\", line 1597, in _validate_input\n    X, y = self._validate_data(\n  File \"/Users/Thomas/opt/anaconda3/envs/wild/lib/python3.9/site-packages/sklearn/base.py\", line 596, in _validate_data\n    X, y = check_X_y(X, y, **check_params)\n  File \"/Users/Thomas/opt/anaconda3/envs/wild/lib/python3.9/site-packages/sklearn/utils/validation.py\", line 1074, in check_X_y\n    X = check_array(\n  File \"/Users/Thomas/opt/anaconda3/envs/wild/lib/python3.9/site-packages/sklearn/utils/validation.py\", line 918, in check_array\n    raise ValueError(\nValueError: Found array with 0 feature(s) (shape=(188, 0)) while a minimum of 1 is required by MLPRegressor.\n\n--------------------------------------------------------------------------------\n1 fits failed with the following error:\nTraceback (most recent call last):\n  File \"/Users/Thomas/opt/anaconda3/envs/wild/lib/python3.9/site-packages/sklearn/model_selection/_validation.py\", line 686, in _fit_and_score\n    estimator.fit(X_train, y_train, **fit_params)\n  File \"/Users/Thomas/opt/anaconda3/envs/wild/lib/python3.9/site-packages/sklearn/pipeline.py\", line 382, in fit\n    self._final_estimator.fit(Xt, y, **fit_params_last_step)\n  File \"/Users/Thomas/opt/anaconda3/envs/wild/lib/python3.9/site-packages/sklearn/neural_network/_multilayer_perceptron.py\", line 762, in fit\n    return self._fit(X, y, incremental=False)\n  File \"/Users/Thomas/opt/anaconda3/envs/wild/lib/python3.9/site-packages/sklearn/neural_network/_multilayer_perceptron.py\", line 394, in _fit\n    X, y = self._validate_input(X, y, incremental, reset=first_pass)\n  File \"/Users/Thomas/opt/anaconda3/envs/wild/lib/python3.9/site-packages/sklearn/neural_network/_multilayer_perceptron.py\", line 1597, in _validate_input\n    X, y = self._validate_data(\n  File \"/Users/Thomas/opt/anaconda3/envs/wild/lib/python3.9/site-packages/sklearn/base.py\", line 596, in _validate_data\n    X, y = check_X_y(X, y, **check_params)\n  File \"/Users/Thomas/opt/anaconda3/envs/wild/lib/python3.9/site-packages/sklearn/utils/validation.py\", line 1074, in check_X_y\n    X = check_array(\n  File \"/Users/Thomas/opt/anaconda3/envs/wild/lib/python3.9/site-packages/sklearn/utils/validation.py\", line 918, in check_array\n    raise ValueError(\nValueError: Found array with 0 feature(s) (shape=(250, 0)) while a minimum of 1 is required by MLPRegressor.\n\n--------------------------------------------------------------------------------\n1 fits failed with the following error:\nTraceback (most recent call last):\n  File \"/Users/Thomas/opt/anaconda3/envs/wild/lib/python3.9/site-packages/sklearn/model_selection/_validation.py\", line 686, in _fit_and_score\n    estimator.fit(X_train, y_train, **fit_params)\n  File \"/Users/Thomas/opt/anaconda3/envs/wild/lib/python3.9/site-packages/sklearn/pipeline.py\", line 382, in fit\n    self._final_estimator.fit(Xt, y, **fit_params_last_step)\n  File \"/Users/Thomas/opt/anaconda3/envs/wild/lib/python3.9/site-packages/sklearn/neural_network/_multilayer_perceptron.py\", line 762, in fit\n    return self._fit(X, y, incremental=False)\n  File \"/Users/Thomas/opt/anaconda3/envs/wild/lib/python3.9/site-packages/sklearn/neural_network/_multilayer_perceptron.py\", line 394, in _fit\n    X, y = self._validate_input(X, y, incremental, reset=first_pass)\n  File \"/Users/Thomas/opt/anaconda3/envs/wild/lib/python3.9/site-packages/sklearn/neural_network/_multilayer_perceptron.py\", line 1597, in _validate_input\n    X, y = self._validate_data(\n  File \"/Users/Thomas/opt/anaconda3/envs/wild/lib/python3.9/site-packages/sklearn/base.py\", line 596, in _validate_data\n    X, y = check_X_y(X, y, **check_params)\n  File \"/Users/Thomas/opt/anaconda3/envs/wild/lib/python3.9/site-packages/sklearn/utils/validation.py\", line 1074, in check_X_y\n    X = check_array(\n  File \"/Users/Thomas/opt/anaconda3/envs/wild/lib/python3.9/site-packages/sklearn/utils/validation.py\", line 918, in check_array\n    raise ValueError(\nValueError: Found array with 0 feature(s) (shape=(312, 0)) while a minimum of 1 is required by MLPRegressor.\n\n\n--------------------------------------------------------------------------------\n1 fits failed with the following error:\nTraceback (most recent call last):\n  File \"/Users/Thomas/opt/anaconda3/envs/wild/lib/python3.9/site-packages/sklearn/model_selection/_validation.py\", line 686, in _fit_and_score\n    estimator.fit(X_train, y_train, **fit_params)\n  File \"/Users/Thomas/opt/anaconda3/envs/wild/lib/python3.9/site-packages/sklearn/model_selection/_search.py\", line 875, in fit\n    self._run_search(evaluate_candidates)\n  File \"/Users/Thomas/opt/anaconda3/envs/wild/lib/python3.9/site-packages/sklearn/model_selection/_search.py\", line 1379, in _run_search\n    evaluate_candidates(ParameterGrid(self.param_grid))\n  File \"/Users/Thomas/opt/anaconda3/envs/wild/lib/python3.9/site-packages/sklearn/model_selection/_search.py\", line 852, in evaluate_candidates\n    _warn_or_raise_about_fit_failures(out, self.error_score)\n  File \"/Users/Thomas/opt/anaconda3/envs/wild/lib/python3.9/site-packages/sklearn/model_selection/_validation.py\", line 367, in _warn_or_raise_about_fit_failures\n    raise ValueError(all_fits_failed_message)\nValueError: \nAll the 5 fits failed.\nIt is very likely that your model is misconfigured.\nYou can try to debug the error by setting error_score='raise'.\n\nBelow are more details about the failures:\n--------------------------------------------------------------------------------\n1 fits failed with the following error:\nTraceback (most recent call last):\n  File \"/Users/Thomas/opt/anaconda3/envs/wild/lib/python3.9/site-packages/sklearn/model_selection/_validation.py\", line 686, in _fit_and_score\n    estimator.fit(X_train, y_train, **fit_params)\n  File \"/Users/Thomas/opt/anaconda3/envs/wild/lib/python3.9/site-packages/sklearn/pipeline.py\", line 382, in fit\n    self._final_estimator.fit(Xt, y, **fit_params_last_step)\n  File \"/Users/Thomas/opt/anaconda3/envs/wild/lib/python3.9/site-packages/sklearn/neural_network/_multilayer_perceptron.py\", line 762, in fit\n    return self._fit(X, y, incremental=False)\n  File \"/Users/Thomas/opt/anaconda3/envs/wild/lib/python3.9/site-packages/sklearn/neural_network/_multilayer_perceptron.py\", line 394, in _fit\n    X, y = self._validate_input(X, y, incremental, reset=first_pass)\n  File \"/Users/Thomas/opt/anaconda3/envs/wild/lib/python3.9/site-packages/sklearn/neural_network/_multilayer_perceptron.py\", line 1597, in _validate_input\n    X, y = self._validate_data(\n  File \"/Users/Thomas/opt/anaconda3/envs/wild/lib/python3.9/site-packages/sklearn/base.py\", line 596, in _validate_data\n    X, y = check_X_y(X, y, **check_params)\n  File \"/Users/Thomas/opt/anaconda3/envs/wild/lib/python3.9/site-packages/sklearn/utils/validation.py\", line 1074, in check_X_y\n    X = check_array(\n  File \"/Users/Thomas/opt/anaconda3/envs/wild/lib/python3.9/site-packages/sklearn/utils/validation.py\", line 918, in check_array\n    raise ValueError(\nValueError: Found array with 0 feature(s) (shape=(82, 0)) while a minimum of 1 is required by MLPRegressor.\n\n--------------------------------------------------------------------------------\n1 fits failed with the following error:\nTraceback (most recent call last):\n  File \"/Users/Thomas/opt/anaconda3/envs/wild/lib/python3.9/site-packages/sklearn/model_selection/_validation.py\", line 686, in _fit_and_score\n    estimator.fit(X_train, y_train, **fit_params)\n  File \"/Users/Thomas/opt/anaconda3/envs/wild/lib/python3.9/site-packages/sklearn/pipeline.py\", line 382, in fit\n    self._final_estimator.fit(Xt, y, **fit_params_last_step)\n  File \"/Users/Thomas/opt/anaconda3/envs/wild/lib/python3.9/site-packages/sklearn/neural_network/_multilayer_perceptron.py\", line 762, in fit\n    return self._fit(X, y, incremental=False)\n  File \"/Users/Thomas/opt/anaconda3/envs/wild/lib/python3.9/site-packages/sklearn/neural_network/_multilayer_perceptron.py\", line 394, in _fit\n    X, y = self._validate_input(X, y, incremental, reset=first_pass)\n  File \"/Users/Thomas/opt/anaconda3/envs/wild/lib/python3.9/site-packages/sklearn/neural_network/_multilayer_perceptron.py\", line 1597, in _validate_input\n    X, y = self._validate_data(\n  File \"/Users/Thomas/opt/anaconda3/envs/wild/lib/python3.9/site-packages/sklearn/base.py\", line 596, in _validate_data\n    X, y = check_X_y(X, y, **check_params)\n  File \"/Users/Thomas/opt/anaconda3/envs/wild/lib/python3.9/site-packages/sklearn/utils/validation.py\", line 1074, in check_X_y\n    X = check_array(\n  File \"/Users/Thomas/opt/anaconda3/envs/wild/lib/python3.9/site-packages/sklearn/utils/validation.py\", line 918, in check_array\n    raise ValueError(\nValueError: Found array with 0 feature(s) (shape=(159, 0)) while a minimum of 1 is required by MLPRegressor.\n\n--------------------------------------------------------------------------------\n1 fits failed with the following error:\nTraceback (most recent call last):\n  File \"/Users/Thomas/opt/anaconda3/envs/wild/lib/python3.9/site-packages/sklearn/model_selection/_validation.py\", line 686, in _fit_and_score\n    estimator.fit(X_train, y_train, **fit_params)\n  File \"/Users/Thomas/opt/anaconda3/envs/wild/lib/python3.9/site-packages/sklearn/pipeline.py\", line 382, in fit\n    self._final_estimator.fit(Xt, y, **fit_params_last_step)\n  File \"/Users/Thomas/opt/anaconda3/envs/wild/lib/python3.9/site-packages/sklearn/neural_network/_multilayer_perceptron.py\", line 762, in fit\n    return self._fit(X, y, incremental=False)\n  File \"/Users/Thomas/opt/anaconda3/envs/wild/lib/python3.9/site-packages/sklearn/neural_network/_multilayer_perceptron.py\", line 394, in _fit\n    X, y = self._validate_input(X, y, incremental, reset=first_pass)\n  File \"/Users/Thomas/opt/anaconda3/envs/wild/lib/python3.9/site-packages/sklearn/neural_network/_multilayer_perceptron.py\", line 1597, in _validate_input\n    X, y = self._validate_data(\n  File \"/Users/Thomas/opt/anaconda3/envs/wild/lib/python3.9/site-packages/sklearn/base.py\", line 596, in _validate_data\n    X, y = check_X_y(X, y, **check_params)\n  File \"/Users/Thomas/opt/anaconda3/envs/wild/lib/python3.9/site-packages/sklearn/utils/validation.py\", line 1074, in check_X_y\n    X = check_array(\n  File \"/Users/Thomas/opt/anaconda3/envs/wild/lib/python3.9/site-packages/sklearn/utils/validation.py\", line 918, in check_array\n    raise ValueError(\nValueError: Found array with 0 feature(s) (shape=(236, 0)) while a minimum of 1 is required by MLPRegressor.\n\n--------------------------------------------------------------------------------\n1 fits failed with the following error:\nTraceback (most recent call last):\n  File \"/Users/Thomas/opt/anaconda3/envs/wild/lib/python3.9/site-packages/sklearn/model_selection/_validation.py\", line 686, in _fit_and_score\n    estimator.fit(X_train, y_train, **fit_params)\n  File \"/Users/Thomas/opt/anaconda3/envs/wild/lib/python3.9/site-packages/sklearn/pipeline.py\", line 382, in fit\n    self._final_estimator.fit(Xt, y, **fit_params_last_step)\n  File \"/Users/Thomas/opt/anaconda3/envs/wild/lib/python3.9/site-packages/sklearn/neural_network/_multilayer_perceptron.py\", line 762, in fit\n    return self._fit(X, y, incremental=False)\n  File \"/Users/Thomas/opt/anaconda3/envs/wild/lib/python3.9/site-packages/sklearn/neural_network/_multilayer_perceptron.py\", line 394, in _fit\n    X, y = self._validate_input(X, y, incremental, reset=first_pass)\n  File \"/Users/Thomas/opt/anaconda3/envs/wild/lib/python3.9/site-packages/sklearn/neural_network/_multilayer_perceptron.py\", line 1597, in _validate_input\n    X, y = self._validate_data(\n  File \"/Users/Thomas/opt/anaconda3/envs/wild/lib/python3.9/site-packages/sklearn/base.py\", line 596, in _validate_data\n    X, y = check_X_y(X, y, **check_params)\n  File \"/Users/Thomas/opt/anaconda3/envs/wild/lib/python3.9/site-packages/sklearn/utils/validation.py\", line 1074, in check_X_y\n    X = check_array(\n  File \"/Users/Thomas/opt/anaconda3/envs/wild/lib/python3.9/site-packages/sklearn/utils/validation.py\", line 918, in check_array\n    raise ValueError(\nValueError: Found array with 0 feature(s) (shape=(313, 0)) while a minimum of 1 is required by MLPRegressor.\n\n--------------------------------------------------------------------------------\n1 fits failed with the following error:\nTraceback (most recent call last):\n  File \"/Users/Thomas/opt/anaconda3/envs/wild/lib/python3.9/site-packages/sklearn/model_selection/_validation.py\", line 686, in _fit_and_score\n    estimator.fit(X_train, y_train, **fit_params)\n  File \"/Users/Thomas/opt/anaconda3/envs/wild/lib/python3.9/site-packages/sklearn/pipeline.py\", line 382, in fit\n    self._final_estimator.fit(Xt, y, **fit_params_last_step)\n  File \"/Users/Thomas/opt/anaconda3/envs/wild/lib/python3.9/site-packages/sklearn/neural_network/_multilayer_perceptron.py\", line 762, in fit\n    return self._fit(X, y, incremental=False)\n  File \"/Users/Thomas/opt/anaconda3/envs/wild/lib/python3.9/site-packages/sklearn/neural_network/_multilayer_perceptron.py\", line 394, in _fit\n    X, y = self._validate_input(X, y, incremental, reset=first_pass)\n  File \"/Users/Thomas/opt/anaconda3/envs/wild/lib/python3.9/site-packages/sklearn/neural_network/_multilayer_perceptron.py\", line 1597, in _validate_input\n    X, y = self._validate_data(\n  File \"/Users/Thomas/opt/anaconda3/envs/wild/lib/python3.9/site-packages/sklearn/base.py\", line 596, in _validate_data\n    X, y = check_X_y(X, y, **check_params)\n  File \"/Users/Thomas/opt/anaconda3/envs/wild/lib/python3.9/site-packages/sklearn/utils/validation.py\", line 1074, in check_X_y\n    X = check_array(\n  File \"/Users/Thomas/opt/anaconda3/envs/wild/lib/python3.9/site-packages/sklearn/utils/validation.py\", line 918, in check_array\n    raise ValueError(\nValueError: Found array with 0 feature(s) (shape=(390, 0)) while a minimum of 1 is required by MLPRegressor.\n\n"
     ]
    }
   ],
   "source": [
    "tscv = TimeSeriesSplit(n_splits=5)\n",
    "pipeline = GridSearchCV(pipeline, param_grid=parameters, n_jobs=15, cv= tscv)\n",
    "\n",
    "pipeline.fit(train_X, np.ravel(train_y))\n",
    "\n",
    "bestParams = pipeline.best_params_\n",
    "\n",
    "predicted_qualities = pipeline.predict(test_X)\n",
    "\n",
    "(rmse, mae, r2) = eval_metrics(test_y, predicted_qualities)\n",
    "\n",
    "print(bestParams)\n",
    "print(\"  RMSE: %s\" % rmse)\n",
    "print(\"  MAE: %s\" % mae)\n",
    "print(\"  R2: %s\" % r2)"
   ]
  },
  {
   "attachments": {},
   "cell_type": "markdown",
   "metadata": {},
   "source": [
    "## Ridge Regression\n",
    "\n",
    "https://scikit-learn.org/stable/modules/generated/sklearn.linear_model.Ridge.html"
   ]
  },
  {
   "cell_type": "code",
   "execution_count": 13,
   "metadata": {},
   "outputs": [],
   "source": [
    "# pipeline = Pipeline(steps=[\n",
    "#     (\"column_transformers\", ColumnTransformer([\n",
    "# #        (\"direction_degree_transformer\", WindDegreeTransformer(), [\"Direction\"]),\n",
    "#         (\"polynomial_features\", PolynomialFeatures() , [\"Speed\"])\n",
    "#     ])),\n",
    "# \t(\"linear_model\", Ridge())\n",
    "# ])\n",
    "# parameters = {\n",
    "#     'column_transformers__polynomial_features__degree':[1,2,3,4,5,6,7,8],\n",
    "# \t\"linear_model__alpha\":[0.001, 0.01, 0.1, 1, 10, 100]\n",
    "# }"
   ]
  },
  {
   "cell_type": "code",
   "execution_count": 14,
   "metadata": {},
   "outputs": [
    {
     "name": "stderr",
     "output_type": "stream",
     "text": [
      "/Users/Thomas/opt/anaconda3/envs/wild/lib/python3.9/site-packages/sklearn/linear_model/_ridge.py:212: LinAlgWarning: Ill-conditioned matrix (rcond=6.28435e-17): result may not be accurate.\n",
      "  return linalg.solve(A, Xy, assume_a=\"pos\", overwrite_a=True).T\n",
      "/Users/Thomas/opt/anaconda3/envs/wild/lib/python3.9/site-packages/sklearn/linear_model/_ridge.py:212: LinAlgWarning: Ill-conditioned matrix (rcond=5.75415e-17): result may not be accurate.\n",
      "  return linalg.solve(A, Xy, assume_a=\"pos\", overwrite_a=True).T\n",
      "/Users/Thomas/opt/anaconda3/envs/wild/lib/python3.9/site-packages/sklearn/linear_model/_ridge.py:212: LinAlgWarning: Ill-conditioned matrix (rcond=2.95377e-17): result may not be accurate.\n",
      "  return linalg.solve(A, Xy, assume_a=\"pos\", overwrite_a=True).T\n",
      "/Users/Thomas/opt/anaconda3/envs/wild/lib/python3.9/site-packages/sklearn/linear_model/_ridge.py:212: LinAlgWarning: Ill-conditioned matrix (rcond=5.75415e-18): result may not be accurate.\n",
      "  return linalg.solve(A, Xy, assume_a=\"pos\", overwrite_a=True).T\n",
      "/Users/Thomas/opt/anaconda3/envs/wild/lib/python3.9/site-packages/sklearn/linear_model/_ridge.py:212: LinAlgWarning: Ill-conditioned matrix (rcond=3.05834e-18): result may not be accurate.\n",
      "  return linalg.solve(A, Xy, assume_a=\"pos\", overwrite_a=True).T\n",
      "/Users/Thomas/opt/anaconda3/envs/wild/lib/python3.9/site-packages/sklearn/linear_model/_ridge.py:212: LinAlgWarning: Ill-conditioned matrix (rcond=3.05834e-17): result may not be accurate.\n",
      "  return linalg.solve(A, Xy, assume_a=\"pos\", overwrite_a=True).T\n",
      "/Users/Thomas/opt/anaconda3/envs/wild/lib/python3.9/site-packages/sklearn/linear_model/_ridge.py:212: LinAlgWarning: Ill-conditioned matrix (rcond=2.95377e-18): result may not be accurate.\n",
      "  return linalg.solve(A, Xy, assume_a=\"pos\", overwrite_a=True).T\n",
      "/Users/Thomas/opt/anaconda3/envs/wild/lib/python3.9/site-packages/sklearn/linear_model/_ridge.py:212: LinAlgWarning: Ill-conditioned matrix (rcond=2.39182e-19): result may not be accurate.\n",
      "  return linalg.solve(A, Xy, assume_a=\"pos\", overwrite_a=True).T\n",
      "/Users/Thomas/opt/anaconda3/envs/wild/lib/python3.9/site-packages/sklearn/linear_model/_ridge.py:212: LinAlgWarning: Ill-conditioned matrix (rcond=6.27746e-17): result may not be accurate.\n",
      "  return linalg.solve(A, Xy, assume_a=\"pos\", overwrite_a=True).T\n",
      "/Users/Thomas/opt/anaconda3/envs/wild/lib/python3.9/site-packages/sklearn/linear_model/_ridge.py:212: LinAlgWarning: Ill-conditioned matrix (rcond=6.52827e-20): result may not be accurate.\n",
      "  return linalg.solve(A, Xy, assume_a=\"pos\", overwrite_a=True).T\n",
      "/Users/Thomas/opt/anaconda3/envs/wild/lib/python3.9/site-packages/sklearn/linear_model/_ridge.py:212: LinAlgWarning: Ill-conditioned matrix (rcond=1.24944e-17): result may not be accurate.\n",
      "  return linalg.solve(A, Xy, assume_a=\"pos\", overwrite_a=True).T\n",
      "/Users/Thomas/opt/anaconda3/envs/wild/lib/python3.9/site-packages/sklearn/linear_model/_ridge.py:212: LinAlgWarning: Ill-conditioned matrix (rcond=6.69016e-19): result may not be accurate.\n",
      "  return linalg.solve(A, Xy, assume_a=\"pos\", overwrite_a=True).T\n",
      "/Users/Thomas/opt/anaconda3/envs/wild/lib/python3.9/site-packages/sklearn/linear_model/_ridge.py:212: LinAlgWarning: Ill-conditioned matrix (rcond=2.39182e-18): result may not be accurate.\n",
      "  return linalg.solve(A, Xy, assume_a=\"pos\", overwrite_a=True).T\n",
      "/Users/Thomas/opt/anaconda3/envs/wild/lib/python3.9/site-packages/sklearn/linear_model/_ridge.py:212: LinAlgWarning: Ill-conditioned matrix (rcond=6.69016e-18): result may not be accurate.\n",
      "  return linalg.solve(A, Xy, assume_a=\"pos\", overwrite_a=True).T\n",
      "/Users/Thomas/opt/anaconda3/envs/wild/lib/python3.9/site-packages/sklearn/linear_model/_ridge.py:212: LinAlgWarning: Ill-conditioned matrix (rcond=6.52827e-19): result may not be accurate.\n",
      "  return linalg.solve(A, Xy, assume_a=\"pos\", overwrite_a=True).T\n",
      "/Users/Thomas/opt/anaconda3/envs/wild/lib/python3.9/site-packages/sklearn/linear_model/_ridge.py:212: LinAlgWarning: Ill-conditioned matrix (rcond=1.41105e-23): result may not be accurate.\n",
      "  return linalg.solve(A, Xy, assume_a=\"pos\", overwrite_a=True).T\n",
      "/Users/Thomas/opt/anaconda3/envs/wild/lib/python3.9/site-packages/sklearn/linear_model/_ridge.py:212: LinAlgWarning: Ill-conditioned matrix (rcond=2.55772e-22): result may not be accurate.\n",
      "  return linalg.solve(A, Xy, assume_a=\"pos\", overwrite_a=True).T\n",
      "/Users/Thomas/opt/anaconda3/envs/wild/lib/python3.9/site-packages/sklearn/linear_model/_ridge.py:212: LinAlgWarning: Ill-conditioned matrix (rcond=1.386e-23): result may not be accurate.\n",
      "  return linalg.solve(A, Xy, assume_a=\"pos\", overwrite_a=True).T\n",
      "/Users/Thomas/opt/anaconda3/envs/wild/lib/python3.9/site-packages/sklearn/linear_model/_ridge.py:212: LinAlgWarning: Ill-conditioned matrix (rcond=9.00742e-20): result may not be accurate.\n",
      "  return linalg.solve(A, Xy, assume_a=\"pos\", overwrite_a=True).T\n",
      "/Users/Thomas/opt/anaconda3/envs/wild/lib/python3.9/site-packages/sklearn/linear_model/_ridge.py:212: LinAlgWarning: Ill-conditioned matrix (rcond=1.24944e-19): result may not be accurate.\n",
      "  return linalg.solve(A, Xy, assume_a=\"pos\", overwrite_a=True).T\n",
      "/Users/Thomas/opt/anaconda3/envs/wild/lib/python3.9/site-packages/sklearn/linear_model/_ridge.py:212: LinAlgWarning: Ill-conditioned matrix (rcond=6.27765e-17): result may not be accurate.\n",
      "  return linalg.solve(A, Xy, assume_a=\"pos\", overwrite_a=True).T\n",
      "/Users/Thomas/opt/anaconda3/envs/wild/lib/python3.9/site-packages/sklearn/linear_model/_ridge.py:212: LinAlgWarning: Ill-conditioned matrix (rcond=1.41105e-22): result may not be accurate.\n",
      "  return linalg.solve(A, Xy, assume_a=\"pos\", overwrite_a=True).T\n",
      "/Users/Thomas/opt/anaconda3/envs/wild/lib/python3.9/site-packages/sklearn/linear_model/_ridge.py:212: LinAlgWarning: Ill-conditioned matrix (rcond=6.69016e-20): result may not be accurate.\n",
      "  return linalg.solve(A, Xy, assume_a=\"pos\", overwrite_a=True).T\n",
      "/Users/Thomas/opt/anaconda3/envs/wild/lib/python3.9/site-packages/sklearn/linear_model/_ridge.py:212: LinAlgWarning: Ill-conditioned matrix (rcond=6.52827e-18): result may not be accurate.\n",
      "  return linalg.solve(A, Xy, assume_a=\"pos\", overwrite_a=True).T\n",
      "/Users/Thomas/opt/anaconda3/envs/wild/lib/python3.9/site-packages/sklearn/linear_model/_ridge.py:212: LinAlgWarning: Ill-conditioned matrix (rcond=2.55772e-21): result may not be accurate.\n",
      "  return linalg.solve(A, Xy, assume_a=\"pos\", overwrite_a=True).T\n",
      "/Users/Thomas/opt/anaconda3/envs/wild/lib/python3.9/site-packages/sklearn/linear_model/_ridge.py:212: LinAlgWarning: Ill-conditioned matrix (rcond=3.76923e-20): result may not be accurate.\n",
      "  return linalg.solve(A, Xy, assume_a=\"pos\", overwrite_a=True).T\n",
      "/Users/Thomas/opt/anaconda3/envs/wild/lib/python3.9/site-packages/sklearn/linear_model/_ridge.py:212: LinAlgWarning: Ill-conditioned matrix (rcond=2.39182e-17): result may not be accurate.\n",
      "  return linalg.solve(A, Xy, assume_a=\"pos\", overwrite_a=True).T\n",
      "/Users/Thomas/opt/anaconda3/envs/wild/lib/python3.9/site-packages/sklearn/linear_model/_ridge.py:212: LinAlgWarning: Ill-conditioned matrix (rcond=6.36468e-17): result may not be accurate.\n",
      "  return linalg.solve(A, Xy, assume_a=\"pos\", overwrite_a=True).T\n",
      "/Users/Thomas/opt/anaconda3/envs/wild/lib/python3.9/site-packages/sklearn/linear_model/_ridge.py:212: LinAlgWarning: Ill-conditioned matrix (rcond=1.386e-22): result may not be accurate.\n",
      "  return linalg.solve(A, Xy, assume_a=\"pos\", overwrite_a=True).T\n",
      "/Users/Thomas/opt/anaconda3/envs/wild/lib/python3.9/site-packages/sklearn/linear_model/_ridge.py:212: LinAlgWarning: Ill-conditioned matrix (rcond=6.27746e-18): result may not be accurate.\n",
      "  return linalg.solve(A, Xy, assume_a=\"pos\", overwrite_a=True).T\n",
      "/Users/Thomas/opt/anaconda3/envs/wild/lib/python3.9/site-packages/sklearn/linear_model/_ridge.py:212: LinAlgWarning: Ill-conditioned matrix (rcond=9.00742e-22): result may not be accurate.\n",
      "  return linalg.solve(A, Xy, assume_a=\"pos\", overwrite_a=True).T\n",
      "/Users/Thomas/opt/anaconda3/envs/wild/lib/python3.9/site-packages/sklearn/linear_model/_ridge.py:212: LinAlgWarning: Ill-conditioned matrix (rcond=1.24944e-20): result may not be accurate.\n",
      "  return linalg.solve(A, Xy, assume_a=\"pos\", overwrite_a=True).T\n",
      "/Users/Thomas/opt/anaconda3/envs/wild/lib/python3.9/site-packages/sklearn/linear_model/_ridge.py:212: LinAlgWarning: Ill-conditioned matrix (rcond=1.41105e-21): result may not be accurate.\n",
      "  return linalg.solve(A, Xy, assume_a=\"pos\", overwrite_a=True).T\n",
      "/Users/Thomas/opt/anaconda3/envs/wild/lib/python3.9/site-packages/sklearn/linear_model/_ridge.py:212: LinAlgWarning: Ill-conditioned matrix (rcond=1.24944e-18): result may not be accurate.\n",
      "  return linalg.solve(A, Xy, assume_a=\"pos\", overwrite_a=True).T\n",
      "/Users/Thomas/opt/anaconda3/envs/wild/lib/python3.9/site-packages/sklearn/linear_model/_ridge.py:212: LinAlgWarning: Ill-conditioned matrix (rcond=3.76923e-19): result may not be accurate.\n",
      "  return linalg.solve(A, Xy, assume_a=\"pos\", overwrite_a=True).T\n",
      "/Users/Thomas/opt/anaconda3/envs/wild/lib/python3.9/site-packages/sklearn/linear_model/_ridge.py:212: LinAlgWarning: Ill-conditioned matrix (rcond=3.14986e-18): result may not be accurate.\n",
      "  return linalg.solve(A, Xy, assume_a=\"pos\", overwrite_a=True).T\n",
      "/Users/Thomas/opt/anaconda3/envs/wild/lib/python3.9/site-packages/sklearn/linear_model/_ridge.py:212: LinAlgWarning: Ill-conditioned matrix (rcond=6.69016e-21): result may not be accurate.\n",
      "  return linalg.solve(A, Xy, assume_a=\"pos\", overwrite_a=True).T\n",
      "/Users/Thomas/opt/anaconda3/envs/wild/lib/python3.9/site-packages/sklearn/linear_model/_ridge.py:212: LinAlgWarning: Ill-conditioned matrix (rcond=2.55772e-23): result may not be accurate.\n",
      "  return linalg.solve(A, Xy, assume_a=\"pos\", overwrite_a=True).T\n",
      "/Users/Thomas/opt/anaconda3/envs/wild/lib/python3.9/site-packages/sklearn/linear_model/_ridge.py:212: LinAlgWarning: Ill-conditioned matrix (rcond=1.386e-21): result may not be accurate.\n",
      "  return linalg.solve(A, Xy, assume_a=\"pos\", overwrite_a=True).T\n",
      "/Users/Thomas/opt/anaconda3/envs/wild/lib/python3.9/site-packages/sklearn/linear_model/_ridge.py:212: LinAlgWarning: Ill-conditioned matrix (rcond=9.00742e-21): result may not be accurate.\n",
      "  return linalg.solve(A, Xy, assume_a=\"pos\", overwrite_a=True).T\n",
      "/Users/Thomas/opt/anaconda3/envs/wild/lib/python3.9/site-packages/sklearn/linear_model/_ridge.py:212: LinAlgWarning: Ill-conditioned matrix (rcond=6.52827e-21): result may not be accurate.\n",
      "  return linalg.solve(A, Xy, assume_a=\"pos\", overwrite_a=True).T\n",
      "/Users/Thomas/opt/anaconda3/envs/wild/lib/python3.9/site-packages/sklearn/linear_model/_ridge.py:212: LinAlgWarning: Ill-conditioned matrix (rcond=7.5107e-19): result may not be accurate.\n",
      "  return linalg.solve(A, Xy, assume_a=\"pos\", overwrite_a=True).T\n",
      "/Users/Thomas/opt/anaconda3/envs/wild/lib/python3.9/site-packages/sklearn/linear_model/_ridge.py:212: LinAlgWarning: Ill-conditioned matrix (rcond=3.27184e-17): result may not be accurate.\n",
      "  return linalg.solve(A, Xy, assume_a=\"pos\", overwrite_a=True).T\n",
      "/Users/Thomas/opt/anaconda3/envs/wild/lib/python3.9/site-packages/sklearn/linear_model/_ridge.py:212: LinAlgWarning: Ill-conditioned matrix (rcond=2.55772e-20): result may not be accurate.\n",
      "  return linalg.solve(A, Xy, assume_a=\"pos\", overwrite_a=True).T\n",
      "/Users/Thomas/opt/anaconda3/envs/wild/lib/python3.9/site-packages/sklearn/linear_model/_ridge.py:212: LinAlgWarning: Ill-conditioned matrix (rcond=1.41105e-20): result may not be accurate.\n",
      "  return linalg.solve(A, Xy, assume_a=\"pos\", overwrite_a=True).T\n",
      "/Users/Thomas/opt/anaconda3/envs/wild/lib/python3.9/site-packages/sklearn/linear_model/_ridge.py:212: LinAlgWarning: Ill-conditioned matrix (rcond=1.386e-20): result may not be accurate.\n",
      "  return linalg.solve(A, Xy, assume_a=\"pos\", overwrite_a=True).T\n",
      "/Users/Thomas/opt/anaconda3/envs/wild/lib/python3.9/site-packages/sklearn/linear_model/_ridge.py:212: LinAlgWarning: Ill-conditioned matrix (rcond=9.00742e-18): result may not be accurate.\n",
      "  return linalg.solve(A, Xy, assume_a=\"pos\", overwrite_a=True).T\n",
      "/Users/Thomas/opt/anaconda3/envs/wild/lib/python3.9/site-packages/sklearn/linear_model/_ridge.py:212: LinAlgWarning: Ill-conditioned matrix (rcond=2.12219e-19): result may not be accurate.\n",
      "  return linalg.solve(A, Xy, assume_a=\"pos\", overwrite_a=True).T\n",
      "/Users/Thomas/opt/anaconda3/envs/wild/lib/python3.9/site-packages/sklearn/linear_model/_ridge.py:212: LinAlgWarning: Ill-conditioned matrix (rcond=1.16446e-19): result may not be accurate.\n",
      "  return linalg.solve(A, Xy, assume_a=\"pos\", overwrite_a=True).T\n",
      "/Users/Thomas/opt/anaconda3/envs/wild/lib/python3.9/site-packages/sklearn/linear_model/_ridge.py:212: LinAlgWarning: Ill-conditioned matrix (rcond=1.17809e-19): result may not be accurate.\n",
      "  return linalg.solve(A, Xy, assume_a=\"pos\", overwrite_a=True).T\n",
      "/Users/Thomas/opt/anaconda3/envs/wild/lib/python3.9/site-packages/sklearn/linear_model/_ridge.py:212: LinAlgWarning: Ill-conditioned matrix (rcond=7.2948e-17): result may not be accurate.\n",
      "  return linalg.solve(A, Xy, assume_a=\"pos\", overwrite_a=True).T\n",
      "/Users/Thomas/opt/anaconda3/envs/wild/lib/python3.9/site-packages/sklearn/linear_model/_ridge.py:212: LinAlgWarning: Ill-conditioned matrix (rcond=2.55772e-18): result may not be accurate.\n",
      "  return linalg.solve(A, Xy, assume_a=\"pos\", overwrite_a=True).T\n"
     ]
    },
    {
     "name": "stdout",
     "output_type": "stream",
     "text": [
      "{'column_transformers__polynomial_features__degree': 3, 'linear_model__alpha': 0.001}\n",
      "  RMSE: 4.1577791423580965\n",
      "  MAE: 3.2475000182302387\n",
      "  R2: 0.896534397808669\n"
     ]
    },
    {
     "name": "stderr",
     "output_type": "stream",
     "text": [
      "/Users/Thomas/opt/anaconda3/envs/wild/lib/python3.9/site-packages/sklearn/linear_model/_ridge.py:212: LinAlgWarning: Ill-conditioned matrix (rcond=1.41105e-18): result may not be accurate.\n",
      "  return linalg.solve(A, Xy, assume_a=\"pos\", overwrite_a=True).T\n",
      "/Users/Thomas/opt/anaconda3/envs/wild/lib/python3.9/site-packages/sklearn/linear_model/_ridge.py:212: LinAlgWarning: Ill-conditioned matrix (rcond=3.36143e-24): result may not be accurate.\n",
      "  return linalg.solve(A, Xy, assume_a=\"pos\", overwrite_a=True).T\n",
      "/Users/Thomas/opt/anaconda3/envs/wild/lib/python3.9/site-packages/sklearn/linear_model/_ridge.py:212: LinAlgWarning: Ill-conditioned matrix (rcond=1.386e-18): result may not be accurate.\n",
      "  return linalg.solve(A, Xy, assume_a=\"pos\", overwrite_a=True).T\n",
      "/Users/Thomas/opt/anaconda3/envs/wild/lib/python3.9/site-packages/sklearn/linear_model/_ridge.py:212: LinAlgWarning: Ill-conditioned matrix (rcond=2.23241e-22): result may not be accurate.\n",
      "  return linalg.solve(A, Xy, assume_a=\"pos\", overwrite_a=True).T\n",
      "/Users/Thomas/opt/anaconda3/envs/wild/lib/python3.9/site-packages/sklearn/linear_model/_ridge.py:212: LinAlgWarning: Ill-conditioned matrix (rcond=2.88371e-26): result may not be accurate.\n",
      "  return linalg.solve(A, Xy, assume_a=\"pos\", overwrite_a=True).T\n",
      "/Users/Thomas/opt/anaconda3/envs/wild/lib/python3.9/site-packages/sklearn/linear_model/_ridge.py:212: LinAlgWarning: Ill-conditioned matrix (rcond=3.36143e-23): result may not be accurate.\n",
      "  return linalg.solve(A, Xy, assume_a=\"pos\", overwrite_a=True).T\n",
      "/Users/Thomas/opt/anaconda3/envs/wild/lib/python3.9/site-packages/sklearn/linear_model/_ridge.py:212: LinAlgWarning: Ill-conditioned matrix (rcond=2.02604e-21): result may not be accurate.\n",
      "  return linalg.solve(A, Xy, assume_a=\"pos\", overwrite_a=True).T\n",
      "/Users/Thomas/opt/anaconda3/envs/wild/lib/python3.9/site-packages/sklearn/linear_model/_ridge.py:212: LinAlgWarning: Ill-conditioned matrix (rcond=2.84495e-26): result may not be accurate.\n",
      "  return linalg.solve(A, Xy, assume_a=\"pos\", overwrite_a=True).T\n",
      "/Users/Thomas/opt/anaconda3/envs/wild/lib/python3.9/site-packages/sklearn/linear_model/_ridge.py:212: LinAlgWarning: Ill-conditioned matrix (rcond=5.00341e-25): result may not be accurate.\n",
      "  return linalg.solve(A, Xy, assume_a=\"pos\", overwrite_a=True).T\n",
      "/Users/Thomas/opt/anaconda3/envs/wild/lib/python3.9/site-packages/sklearn/linear_model/_ridge.py:212: LinAlgWarning: Ill-conditioned matrix (rcond=2.88371e-25): result may not be accurate.\n",
      "  return linalg.solve(A, Xy, assume_a=\"pos\", overwrite_a=True).T\n",
      "/Users/Thomas/opt/anaconda3/envs/wild/lib/python3.9/site-packages/sklearn/linear_model/_ridge.py:212: LinAlgWarning: Ill-conditioned matrix (rcond=2.23241e-20): result may not be accurate.\n",
      "  return linalg.solve(A, Xy, assume_a=\"pos\", overwrite_a=True).T\n",
      "/Users/Thomas/opt/anaconda3/envs/wild/lib/python3.9/site-packages/sklearn/linear_model/_ridge.py:212: LinAlgWarning: Ill-conditioned matrix (rcond=3.01305e-22): result may not be accurate.\n",
      "  return linalg.solve(A, Xy, assume_a=\"pos\", overwrite_a=True).T\n",
      "/Users/Thomas/opt/anaconda3/envs/wild/lib/python3.9/site-packages/sklearn/linear_model/_ridge.py:212: LinAlgWarning: Ill-conditioned matrix (rcond=2.84495e-25): result may not be accurate.\n",
      "  return linalg.solve(A, Xy, assume_a=\"pos\", overwrite_a=True).T\n",
      "/Users/Thomas/opt/anaconda3/envs/wild/lib/python3.9/site-packages/sklearn/linear_model/_ridge.py:212: LinAlgWarning: Ill-conditioned matrix (rcond=5.00341e-24): result may not be accurate.\n",
      "  return linalg.solve(A, Xy, assume_a=\"pos\", overwrite_a=True).T\n",
      "/Users/Thomas/opt/anaconda3/envs/wild/lib/python3.9/site-packages/sklearn/linear_model/_ridge.py:212: LinAlgWarning: Ill-conditioned matrix (rcond=2.88371e-24): result may not be accurate.\n",
      "  return linalg.solve(A, Xy, assume_a=\"pos\", overwrite_a=True).T\n",
      "/Users/Thomas/opt/anaconda3/envs/wild/lib/python3.9/site-packages/sklearn/linear_model/_ridge.py:212: LinAlgWarning: Ill-conditioned matrix (rcond=4.28323e-23): result may not be accurate.\n",
      "  return linalg.solve(A, Xy, assume_a=\"pos\", overwrite_a=True).T\n",
      "/Users/Thomas/opt/anaconda3/envs/wild/lib/python3.9/site-packages/sklearn/linear_model/_ridge.py:212: LinAlgWarning: Ill-conditioned matrix (rcond=2.608e-23): result may not be accurate.\n",
      "  return linalg.solve(A, Xy, assume_a=\"pos\", overwrite_a=True).T\n",
      "/Users/Thomas/opt/anaconda3/envs/wild/lib/python3.9/site-packages/sklearn/linear_model/_ridge.py:212: LinAlgWarning: Ill-conditioned matrix (rcond=2.08704e-18): result may not be accurate.\n",
      "  return linalg.solve(A, Xy, assume_a=\"pos\", overwrite_a=True).T\n",
      "/Users/Thomas/opt/anaconda3/envs/wild/lib/python3.9/site-packages/sklearn/linear_model/_ridge.py:212: LinAlgWarning: Ill-conditioned matrix (rcond=3.36143e-20): result may not be accurate.\n",
      "  return linalg.solve(A, Xy, assume_a=\"pos\", overwrite_a=True).T\n",
      "/Users/Thomas/opt/anaconda3/envs/wild/lib/python3.9/site-packages/sklearn/linear_model/_ridge.py:212: LinAlgWarning: Ill-conditioned matrix (rcond=2.84495e-24): result may not be accurate.\n",
      "  return linalg.solve(A, Xy, assume_a=\"pos\", overwrite_a=True).T\n",
      "/Users/Thomas/opt/anaconda3/envs/wild/lib/python3.9/site-packages/sklearn/linear_model/_ridge.py:212: LinAlgWarning: Ill-conditioned matrix (rcond=2.57561e-23): result may not be accurate.\n",
      "  return linalg.solve(A, Xy, assume_a=\"pos\", overwrite_a=True).T\n",
      "/Users/Thomas/opt/anaconda3/envs/wild/lib/python3.9/site-packages/sklearn/linear_model/_ridge.py:212: LinAlgWarning: Ill-conditioned matrix (rcond=5.00341e-22): result may not be accurate.\n",
      "  return linalg.solve(A, Xy, assume_a=\"pos\", overwrite_a=True).T\n",
      "/Users/Thomas/opt/anaconda3/envs/wild/lib/python3.9/site-packages/sklearn/linear_model/_ridge.py:212: LinAlgWarning: Ill-conditioned matrix (rcond=5.00341e-26): result may not be accurate.\n",
      "  return linalg.solve(A, Xy, assume_a=\"pos\", overwrite_a=True).T\n",
      "/Users/Thomas/opt/anaconda3/envs/wild/lib/python3.9/site-packages/sklearn/linear_model/_ridge.py:212: LinAlgWarning: Ill-conditioned matrix (rcond=2.89516e-21): result may not be accurate.\n",
      "  return linalg.solve(A, Xy, assume_a=\"pos\", overwrite_a=True).T\n",
      "/Users/Thomas/opt/anaconda3/envs/wild/lib/python3.9/site-packages/sklearn/linear_model/_ridge.py:212: LinAlgWarning: Ill-conditioned matrix (rcond=2.23241e-19): result may not be accurate.\n",
      "  return linalg.solve(A, Xy, assume_a=\"pos\", overwrite_a=True).T\n",
      "/Users/Thomas/opt/anaconda3/envs/wild/lib/python3.9/site-packages/sklearn/linear_model/_ridge.py:212: LinAlgWarning: Ill-conditioned matrix (rcond=2.23241e-17): result may not be accurate.\n",
      "  return linalg.solve(A, Xy, assume_a=\"pos\", overwrite_a=True).T\n",
      "/Users/Thomas/opt/anaconda3/envs/wild/lib/python3.9/site-packages/sklearn/linear_model/_ridge.py:212: LinAlgWarning: Ill-conditioned matrix (rcond=4.13487e-21): result may not be accurate.\n",
      "  return linalg.solve(A, Xy, assume_a=\"pos\", overwrite_a=True).T\n",
      "/Users/Thomas/opt/anaconda3/envs/wild/lib/python3.9/site-packages/sklearn/linear_model/_ridge.py:212: LinAlgWarning: Ill-conditioned matrix (rcond=2.37816e-22): result may not be accurate.\n",
      "  return linalg.solve(A, Xy, assume_a=\"pos\", overwrite_a=True).T\n",
      "/Users/Thomas/opt/anaconda3/envs/wild/lib/python3.9/site-packages/sklearn/linear_model/_ridge.py:212: LinAlgWarning: Ill-conditioned matrix (rcond=2.43371e-22): result may not be accurate.\n",
      "  return linalg.solve(A, Xy, assume_a=\"pos\", overwrite_a=True).T\n",
      "/Users/Thomas/opt/anaconda3/envs/wild/lib/python3.9/site-packages/sklearn/linear_model/_ridge.py:212: LinAlgWarning: Ill-conditioned matrix (rcond=2.84495e-21): result may not be accurate.\n",
      "  return linalg.solve(A, Xy, assume_a=\"pos\", overwrite_a=True).T\n",
      "/Users/Thomas/opt/anaconda3/envs/wild/lib/python3.9/site-packages/sklearn/linear_model/_ridge.py:212: LinAlgWarning: Ill-conditioned matrix (rcond=2.88371e-21): result may not be accurate.\n",
      "  return linalg.solve(A, Xy, assume_a=\"pos\", overwrite_a=True).T\n",
      "/Users/Thomas/opt/anaconda3/envs/wild/lib/python3.9/site-packages/sklearn/linear_model/_ridge.py:212: LinAlgWarning: Ill-conditioned matrix (rcond=2.65992e-19): result may not be accurate.\n",
      "  return linalg.solve(A, Xy, assume_a=\"pos\", overwrite_a=True).T\n"
     ]
    }
   ],
   "source": [
    "# tscv = TimeSeriesSplit(n_splits=5)\n",
    "# pipeline = GridSearchCV(pipeline, param_grid=parameters, n_jobs=15, cv= tscv)\n",
    "\n",
    "# pipeline.fit(train_X, np.ravel(train_y))\n",
    "\n",
    "# bestParams = pipeline.best_params_\n",
    "\n",
    "# predicted_qualities = pipeline.best_estimator_.predict(test_X)\n",
    "\n",
    "# (rmse, mae, r2) = eval_metrics(test_y, predicted_qualities)\n",
    "\n",
    "# print(bestParams)\n",
    "# print(\"  RMSE: %s\" % rmse)\n",
    "# print(\"  MAE: %s\" % mae)\n",
    "# print(\"  R2: %s\" % r2)"
   ]
  }
 ],
 "metadata": {
  "kernelspec": {
   "display_name": "wild",
   "language": "python",
   "name": "python3"
  },
  "language_info": {
   "codemirror_mode": {
    "name": "ipython",
    "version": 3
   },
   "file_extension": ".py",
   "mimetype": "text/x-python",
   "name": "python",
   "nbconvert_exporter": "python",
   "pygments_lexer": "ipython3",
   "version": "3.9.13 (main, Aug 25 2022, 18:29:29) \n[Clang 12.0.0 ]"
  },
  "orig_nbformat": 4,
  "vscode": {
   "interpreter": {
    "hash": "27fd4a01abd6aa8188b72ae394dc16198503c0de54152a5fe8613071c94f3983"
   }
  }
 },
 "nbformat": 4,
 "nbformat_minor": 2
}
